
[2021-03-18 02:15:34] [ERROR] Traceback (most recent call last):
  File "/mnt/data/projects/python/webapp/flask/engilogic/v3/webapp/app/admin/view_admin.py", line 132, in dyn_edit
    res = globals()[tb_name].query.filter_by(id == values.id).update(data)
TypeError: filter_by() takes 1 positional argument but 2 were given
 

[2021-03-18 02:17:22] [ERROR] Traceback (most recent call last):
  File "/mnt/data/projects/python/webapp/flask/engilogic/v3/webapp/app/admin/view_admin.py", line 132, in dyn_edit
    res = globals()[tb_name].query.filter_by(globals()[tb_name].id == id).update(data)
TypeError: filter_by() takes 1 positional argument but 2 were given
 

[2021-03-18 02:21:50] [ERROR] Traceback (most recent call last):
  File "/mnt/data/projects/python/webapp/flask/engilogic/v3/webapp/app/admin/view_admin.py", line 133, in dyn_edit
    cprint("PURPLE", "res: " + res)
TypeError: can only concatenate str (not "int") to str
 

[2021-03-18 02:25:09] [ERROR] Traceback (most recent call last):
  File "/mnt/data/projects/python/webapp/flask/engilogic/v3/venv/lib/python3.8/site-packages/mysql/connector/connection_cext.py", line 507, in cmd_query
    self._cmysql.query(query,
_mysql_connector.MySQLInterfaceError: You have an error in your SQL syntax; check the manual that corresponds to your MySQL server version for the right syntax to use near 'WHERE post.id = '15'' at line 1

During handling of the above exception, another exception occurred:

Traceback (most recent call last):
  File "/mnt/data/projects/python/webapp/flask/engilogic/v3/venv/lib/python3.8/site-packages/sqlalchemy/engine/base.py", line 1276, in _execute_context
    self.dialect.do_execute(
  File "/mnt/data/projects/python/webapp/flask/engilogic/v3/venv/lib/python3.8/site-packages/sqlalchemy/engine/default.py", line 608, in do_execute
    cursor.execute(statement, parameters)
  File "/mnt/data/projects/python/webapp/flask/engilogic/v3/venv/lib/python3.8/site-packages/mysql/connector/cursor_cext.py", line 274, in execute
    result = self._cnx.cmd_query(stmt, raw=self._raw,
  File "/mnt/data/projects/python/webapp/flask/engilogic/v3/venv/lib/python3.8/site-packages/mysql/connector/connection_cext.py", line 511, in cmd_query
    raise errors.get_mysql_exception(exc.errno, msg=exc.msg,
mysql.connector.errors.ProgrammingError: 1064 (42000): You have an error in your SQL syntax; check the manual that corresponds to your MySQL server version for the right syntax to use near 'WHERE post.id = '15'' at line 1

The above exception was the direct cause of the following exception:

Traceback (most recent call last):
  File "/mnt/data/projects/python/webapp/flask/engilogic/v3/webapp/app/admin/view_admin.py", line 134, in dyn_edit
    res = globals()[tb_name].query.filter(globals()[tb_name].id == id).update(data)
  File "/mnt/data/projects/python/webapp/flask/engilogic/v3/venv/lib/python3.8/site-packages/sqlalchemy/orm/query.py", line 4063, in update
    update_op.exec_()
  File "/mnt/data/projects/python/webapp/flask/engilogic/v3/venv/lib/python3.8/site-packages/sqlalchemy/orm/persistence.py", line 1697, in exec_
    self._do_exec()
  File "/mnt/data/projects/python/webapp/flask/engilogic/v3/venv/lib/python3.8/site-packages/sqlalchemy/orm/persistence.py", line 1895, in _do_exec
    self._execute_stmt(update_stmt)
  File "/mnt/data/projects/python/webapp/flask/engilogic/v3/venv/lib/python3.8/site-packages/sqlalchemy/orm/persistence.py", line 1702, in _execute_stmt
    self.result = self.query._execute_crud(stmt, self.mapper)
  File "/mnt/data/projects/python/webapp/flask/engilogic/v3/venv/lib/python3.8/site-packages/sqlalchemy/orm/query.py", line 3568, in _execute_crud
    return conn.execute(stmt, self._params)
  File "/mnt/data/projects/python/webapp/flask/engilogic/v3/venv/lib/python3.8/site-packages/sqlalchemy/engine/base.py", line 1011, in execute
    return meth(self, multiparams, params)
  File "/mnt/data/projects/python/webapp/flask/engilogic/v3/venv/lib/python3.8/site-packages/sqlalchemy/sql/elements.py", line 298, in _execute_on_connection
    return connection._execute_clauseelement(self, multiparams, params)
  File "/mnt/data/projects/python/webapp/flask/engilogic/v3/venv/lib/python3.8/site-packages/sqlalchemy/engine/base.py", line 1124, in _execute_clauseelement
    ret = self._execute_context(
  File "/mnt/data/projects/python/webapp/flask/engilogic/v3/venv/lib/python3.8/site-packages/sqlalchemy/engine/base.py", line 1316, in _execute_context
    self._handle_dbapi_exception(
  File "/mnt/data/projects/python/webapp/flask/engilogic/v3/venv/lib/python3.8/site-packages/sqlalchemy/engine/base.py", line 1510, in _handle_dbapi_exception
    util.raise_(
  File "/mnt/data/projects/python/webapp/flask/engilogic/v3/venv/lib/python3.8/site-packages/sqlalchemy/util/compat.py", line 182, in raise_
    raise exception
  File "/mnt/data/projects/python/webapp/flask/engilogic/v3/venv/lib/python3.8/site-packages/sqlalchemy/engine/base.py", line 1276, in _execute_context
    self.dialect.do_execute(
  File "/mnt/data/projects/python/webapp/flask/engilogic/v3/venv/lib/python3.8/site-packages/sqlalchemy/engine/default.py", line 608, in do_execute
    cursor.execute(statement, parameters)
  File "/mnt/data/projects/python/webapp/flask/engilogic/v3/venv/lib/python3.8/site-packages/mysql/connector/cursor_cext.py", line 274, in execute
    result = self._cnx.cmd_query(stmt, raw=self._raw,
  File "/mnt/data/projects/python/webapp/flask/engilogic/v3/venv/lib/python3.8/site-packages/mysql/connector/connection_cext.py", line 511, in cmd_query
    raise errors.get_mysql_exception(exc.errno, msg=exc.msg,
sqlalchemy.exc.ProgrammingError: (mysql.connector.errors.ProgrammingError) 1064 (42000): You have an error in your SQL syntax; check the manual that corresponds to your MySQL server version for the right syntax to use near 'WHERE post.id = '15'' at line 1
[SQL: UPDATE post SET  WHERE post.id = %(id_1)s]
[parameters: {'id_1': '15'}]
(Background on this error at: http://sqlalche.me/e/13/f405)
 

[2021-03-18 02:26:30] [ERROR] Traceback (most recent call last):
  File "/mnt/data/projects/python/webapp/flask/engilogic/v3/venv/lib/python3.8/site-packages/mysql/connector/connection_cext.py", line 507, in cmd_query
    self._cmysql.query(query,
_mysql_connector.MySQLInterfaceError: You have an error in your SQL syntax; check the manual that corresponds to your MySQL server version for the right syntax to use near 'WHERE post.id = '15'' at line 1

During handling of the above exception, another exception occurred:

Traceback (most recent call last):
  File "/mnt/data/projects/python/webapp/flask/engilogic/v3/venv/lib/python3.8/site-packages/sqlalchemy/engine/base.py", line 1276, in _execute_context
    self.dialect.do_execute(
  File "/mnt/data/projects/python/webapp/flask/engilogic/v3/venv/lib/python3.8/site-packages/sqlalchemy/engine/default.py", line 608, in do_execute
    cursor.execute(statement, parameters)
  File "/mnt/data/projects/python/webapp/flask/engilogic/v3/venv/lib/python3.8/site-packages/mysql/connector/cursor_cext.py", line 274, in execute
    result = self._cnx.cmd_query(stmt, raw=self._raw,
  File "/mnt/data/projects/python/webapp/flask/engilogic/v3/venv/lib/python3.8/site-packages/mysql/connector/connection_cext.py", line 511, in cmd_query
    raise errors.get_mysql_exception(exc.errno, msg=exc.msg,
mysql.connector.errors.ProgrammingError: 1064 (42000): You have an error in your SQL syntax; check the manual that corresponds to your MySQL server version for the right syntax to use near 'WHERE post.id = '15'' at line 1

The above exception was the direct cause of the following exception:

Traceback (most recent call last):
  File "/mnt/data/projects/python/webapp/flask/engilogic/v3/webapp/app/admin/view_admin.py", line 135, in dyn_edit
    res = globals()[tb_name].query.filter(globals()[tb_name].id == id).update(data)
  File "/mnt/data/projects/python/webapp/flask/engilogic/v3/venv/lib/python3.8/site-packages/sqlalchemy/orm/query.py", line 4063, in update
    update_op.exec_()
  File "/mnt/data/projects/python/webapp/flask/engilogic/v3/venv/lib/python3.8/site-packages/sqlalchemy/orm/persistence.py", line 1697, in exec_
    self._do_exec()
  File "/mnt/data/projects/python/webapp/flask/engilogic/v3/venv/lib/python3.8/site-packages/sqlalchemy/orm/persistence.py", line 1895, in _do_exec
    self._execute_stmt(update_stmt)
  File "/mnt/data/projects/python/webapp/flask/engilogic/v3/venv/lib/python3.8/site-packages/sqlalchemy/orm/persistence.py", line 1702, in _execute_stmt
    self.result = self.query._execute_crud(stmt, self.mapper)
  File "/mnt/data/projects/python/webapp/flask/engilogic/v3/venv/lib/python3.8/site-packages/sqlalchemy/orm/query.py", line 3568, in _execute_crud
    return conn.execute(stmt, self._params)
  File "/mnt/data/projects/python/webapp/flask/engilogic/v3/venv/lib/python3.8/site-packages/sqlalchemy/engine/base.py", line 1011, in execute
    return meth(self, multiparams, params)
  File "/mnt/data/projects/python/webapp/flask/engilogic/v3/venv/lib/python3.8/site-packages/sqlalchemy/sql/elements.py", line 298, in _execute_on_connection
    return connection._execute_clauseelement(self, multiparams, params)
  File "/mnt/data/projects/python/webapp/flask/engilogic/v3/venv/lib/python3.8/site-packages/sqlalchemy/engine/base.py", line 1124, in _execute_clauseelement
    ret = self._execute_context(
  File "/mnt/data/projects/python/webapp/flask/engilogic/v3/venv/lib/python3.8/site-packages/sqlalchemy/engine/base.py", line 1316, in _execute_context
    self._handle_dbapi_exception(
  File "/mnt/data/projects/python/webapp/flask/engilogic/v3/venv/lib/python3.8/site-packages/sqlalchemy/engine/base.py", line 1510, in _handle_dbapi_exception
    util.raise_(
  File "/mnt/data/projects/python/webapp/flask/engilogic/v3/venv/lib/python3.8/site-packages/sqlalchemy/util/compat.py", line 182, in raise_
    raise exception
  File "/mnt/data/projects/python/webapp/flask/engilogic/v3/venv/lib/python3.8/site-packages/sqlalchemy/engine/base.py", line 1276, in _execute_context
    self.dialect.do_execute(
  File "/mnt/data/projects/python/webapp/flask/engilogic/v3/venv/lib/python3.8/site-packages/sqlalchemy/engine/default.py", line 608, in do_execute
    cursor.execute(statement, parameters)
  File "/mnt/data/projects/python/webapp/flask/engilogic/v3/venv/lib/python3.8/site-packages/mysql/connector/cursor_cext.py", line 274, in execute
    result = self._cnx.cmd_query(stmt, raw=self._raw,
  File "/mnt/data/projects/python/webapp/flask/engilogic/v3/venv/lib/python3.8/site-packages/mysql/connector/connection_cext.py", line 511, in cmd_query
    raise errors.get_mysql_exception(exc.errno, msg=exc.msg,
sqlalchemy.exc.ProgrammingError: (mysql.connector.errors.ProgrammingError) 1064 (42000): You have an error in your SQL syntax; check the manual that corresponds to your MySQL server version for the right syntax to use near 'WHERE post.id = '15'' at line 1
[SQL: UPDATE post SET  WHERE post.id = %(id_1)s]
[parameters: {'id_1': '15'}]
(Background on this error at: http://sqlalche.me/e/13/f405)
 

[2021-03-18 02:27:58] [ERROR] Traceback (most recent call last):
  File "/mnt/data/projects/python/webapp/flask/engilogic/v3/venv/lib/python3.8/site-packages/mysql/connector/connection_cext.py", line 507, in cmd_query
    self._cmysql.query(query,
_mysql_connector.MySQLInterfaceError: You have an error in your SQL syntax; check the manual that corresponds to your MySQL server version for the right syntax to use near 'WHERE post.id = '15'' at line 1

During handling of the above exception, another exception occurred:

Traceback (most recent call last):
  File "/mnt/data/projects/python/webapp/flask/engilogic/v3/venv/lib/python3.8/site-packages/sqlalchemy/engine/base.py", line 1276, in _execute_context
    self.dialect.do_execute(
  File "/mnt/data/projects/python/webapp/flask/engilogic/v3/venv/lib/python3.8/site-packages/sqlalchemy/engine/default.py", line 608, in do_execute
    cursor.execute(statement, parameters)
  File "/mnt/data/projects/python/webapp/flask/engilogic/v3/venv/lib/python3.8/site-packages/mysql/connector/cursor_cext.py", line 274, in execute
    result = self._cnx.cmd_query(stmt, raw=self._raw,
  File "/mnt/data/projects/python/webapp/flask/engilogic/v3/venv/lib/python3.8/site-packages/mysql/connector/connection_cext.py", line 511, in cmd_query
    raise errors.get_mysql_exception(exc.errno, msg=exc.msg,
mysql.connector.errors.ProgrammingError: 1064 (42000): You have an error in your SQL syntax; check the manual that corresponds to your MySQL server version for the right syntax to use near 'WHERE post.id = '15'' at line 1

The above exception was the direct cause of the following exception:

Traceback (most recent call last):
  File "/mnt/data/projects/python/webapp/flask/engilogic/v3/webapp/app/admin/view_admin.py", line 136, in dyn_edit
    res = globals()[tb_name].query.filter(globals()[tb_name].id == id).update(data)
  File "/mnt/data/projects/python/webapp/flask/engilogic/v3/venv/lib/python3.8/site-packages/sqlalchemy/orm/query.py", line 4063, in update
    update_op.exec_()
  File "/mnt/data/projects/python/webapp/flask/engilogic/v3/venv/lib/python3.8/site-packages/sqlalchemy/orm/persistence.py", line 1697, in exec_
    self._do_exec()
  File "/mnt/data/projects/python/webapp/flask/engilogic/v3/venv/lib/python3.8/site-packages/sqlalchemy/orm/persistence.py", line 1895, in _do_exec
    self._execute_stmt(update_stmt)
  File "/mnt/data/projects/python/webapp/flask/engilogic/v3/venv/lib/python3.8/site-packages/sqlalchemy/orm/persistence.py", line 1702, in _execute_stmt
    self.result = self.query._execute_crud(stmt, self.mapper)
  File "/mnt/data/projects/python/webapp/flask/engilogic/v3/venv/lib/python3.8/site-packages/sqlalchemy/orm/query.py", line 3568, in _execute_crud
    return conn.execute(stmt, self._params)
  File "/mnt/data/projects/python/webapp/flask/engilogic/v3/venv/lib/python3.8/site-packages/sqlalchemy/engine/base.py", line 1011, in execute
    return meth(self, multiparams, params)
  File "/mnt/data/projects/python/webapp/flask/engilogic/v3/venv/lib/python3.8/site-packages/sqlalchemy/sql/elements.py", line 298, in _execute_on_connection
    return connection._execute_clauseelement(self, multiparams, params)
  File "/mnt/data/projects/python/webapp/flask/engilogic/v3/venv/lib/python3.8/site-packages/sqlalchemy/engine/base.py", line 1124, in _execute_clauseelement
    ret = self._execute_context(
  File "/mnt/data/projects/python/webapp/flask/engilogic/v3/venv/lib/python3.8/site-packages/sqlalchemy/engine/base.py", line 1316, in _execute_context
    self._handle_dbapi_exception(
  File "/mnt/data/projects/python/webapp/flask/engilogic/v3/venv/lib/python3.8/site-packages/sqlalchemy/engine/base.py", line 1510, in _handle_dbapi_exception
    util.raise_(
  File "/mnt/data/projects/python/webapp/flask/engilogic/v3/venv/lib/python3.8/site-packages/sqlalchemy/util/compat.py", line 182, in raise_
    raise exception
  File "/mnt/data/projects/python/webapp/flask/engilogic/v3/venv/lib/python3.8/site-packages/sqlalchemy/engine/base.py", line 1276, in _execute_context
    self.dialect.do_execute(
  File "/mnt/data/projects/python/webapp/flask/engilogic/v3/venv/lib/python3.8/site-packages/sqlalchemy/engine/default.py", line 608, in do_execute
    cursor.execute(statement, parameters)
  File "/mnt/data/projects/python/webapp/flask/engilogic/v3/venv/lib/python3.8/site-packages/mysql/connector/cursor_cext.py", line 274, in execute
    result = self._cnx.cmd_query(stmt, raw=self._raw,
  File "/mnt/data/projects/python/webapp/flask/engilogic/v3/venv/lib/python3.8/site-packages/mysql/connector/connection_cext.py", line 511, in cmd_query
    raise errors.get_mysql_exception(exc.errno, msg=exc.msg,
sqlalchemy.exc.ProgrammingError: (mysql.connector.errors.ProgrammingError) 1064 (42000): You have an error in your SQL syntax; check the manual that corresponds to your MySQL server version for the right syntax to use near 'WHERE post.id = '15'' at line 1
[SQL: UPDATE post SET  WHERE post.id = %(id_1)s]
[parameters: {'id_1': '15'}]
(Background on this error at: http://sqlalche.me/e/13/f405)
 

[2021-03-18 03:26:42] [ERROR] Traceback (most recent call last):
  File "/mnt/data/projects/python/webapp/flask/engilogic/v3/venv/lib/python3.8/site-packages/mysql/connector/connection_cext.py", line 507, in cmd_query
    self._cmysql.query(query,
_mysql_connector.MySQLInterfaceError: You have an error in your SQL syntax; check the manual that corresponds to your MySQL server version for the right syntax to use near 'WHERE post.id = '15'' at line 1

During handling of the above exception, another exception occurred:

Traceback (most recent call last):
  File "/mnt/data/projects/python/webapp/flask/engilogic/v3/venv/lib/python3.8/site-packages/sqlalchemy/engine/base.py", line 1276, in _execute_context
    self.dialect.do_execute(
  File "/mnt/data/projects/python/webapp/flask/engilogic/v3/venv/lib/python3.8/site-packages/sqlalchemy/engine/default.py", line 608, in do_execute
    cursor.execute(statement, parameters)
  File "/mnt/data/projects/python/webapp/flask/engilogic/v3/venv/lib/python3.8/site-packages/mysql/connector/cursor_cext.py", line 274, in execute
    result = self._cnx.cmd_query(stmt, raw=self._raw,
  File "/mnt/data/projects/python/webapp/flask/engilogic/v3/venv/lib/python3.8/site-packages/mysql/connector/connection_cext.py", line 511, in cmd_query
    raise errors.get_mysql_exception(exc.errno, msg=exc.msg,
mysql.connector.errors.ProgrammingError: 1064 (42000): You have an error in your SQL syntax; check the manual that corresponds to your MySQL server version for the right syntax to use near 'WHERE post.id = '15'' at line 1

The above exception was the direct cause of the following exception:

Traceback (most recent call last):
  File "/mnt/data/projects/python/webapp/flask/engilogic/v3/webapp/app/admin/view_admin.py", line 138, in dyn_edit
    res = globals()[tb_name].query.filter(globals()[tb_name].id == id).update(data)
  File "/mnt/data/projects/python/webapp/flask/engilogic/v3/venv/lib/python3.8/site-packages/sqlalchemy/orm/query.py", line 4063, in update
    update_op.exec_()
  File "/mnt/data/projects/python/webapp/flask/engilogic/v3/venv/lib/python3.8/site-packages/sqlalchemy/orm/persistence.py", line 1697, in exec_
    self._do_exec()
  File "/mnt/data/projects/python/webapp/flask/engilogic/v3/venv/lib/python3.8/site-packages/sqlalchemy/orm/persistence.py", line 1895, in _do_exec
    self._execute_stmt(update_stmt)
  File "/mnt/data/projects/python/webapp/flask/engilogic/v3/venv/lib/python3.8/site-packages/sqlalchemy/orm/persistence.py", line 1702, in _execute_stmt
    self.result = self.query._execute_crud(stmt, self.mapper)
  File "/mnt/data/projects/python/webapp/flask/engilogic/v3/venv/lib/python3.8/site-packages/sqlalchemy/orm/query.py", line 3568, in _execute_crud
    return conn.execute(stmt, self._params)
  File "/mnt/data/projects/python/webapp/flask/engilogic/v3/venv/lib/python3.8/site-packages/sqlalchemy/engine/base.py", line 1011, in execute
    return meth(self, multiparams, params)
  File "/mnt/data/projects/python/webapp/flask/engilogic/v3/venv/lib/python3.8/site-packages/sqlalchemy/sql/elements.py", line 298, in _execute_on_connection
    return connection._execute_clauseelement(self, multiparams, params)
  File "/mnt/data/projects/python/webapp/flask/engilogic/v3/venv/lib/python3.8/site-packages/sqlalchemy/engine/base.py", line 1124, in _execute_clauseelement
    ret = self._execute_context(
  File "/mnt/data/projects/python/webapp/flask/engilogic/v3/venv/lib/python3.8/site-packages/sqlalchemy/engine/base.py", line 1316, in _execute_context
    self._handle_dbapi_exception(
  File "/mnt/data/projects/python/webapp/flask/engilogic/v3/venv/lib/python3.8/site-packages/sqlalchemy/engine/base.py", line 1510, in _handle_dbapi_exception
    util.raise_(
  File "/mnt/data/projects/python/webapp/flask/engilogic/v3/venv/lib/python3.8/site-packages/sqlalchemy/util/compat.py", line 182, in raise_
    raise exception
  File "/mnt/data/projects/python/webapp/flask/engilogic/v3/venv/lib/python3.8/site-packages/sqlalchemy/engine/base.py", line 1276, in _execute_context
    self.dialect.do_execute(
  File "/mnt/data/projects/python/webapp/flask/engilogic/v3/venv/lib/python3.8/site-packages/sqlalchemy/engine/default.py", line 608, in do_execute
    cursor.execute(statement, parameters)
  File "/mnt/data/projects/python/webapp/flask/engilogic/v3/venv/lib/python3.8/site-packages/mysql/connector/cursor_cext.py", line 274, in execute
    result = self._cnx.cmd_query(stmt, raw=self._raw,
  File "/mnt/data/projects/python/webapp/flask/engilogic/v3/venv/lib/python3.8/site-packages/mysql/connector/connection_cext.py", line 511, in cmd_query
    raise errors.get_mysql_exception(exc.errno, msg=exc.msg,
sqlalchemy.exc.ProgrammingError: (mysql.connector.errors.ProgrammingError) 1064 (42000): You have an error in your SQL syntax; check the manual that corresponds to your MySQL server version for the right syntax to use near 'WHERE post.id = '15'' at line 1
[SQL: UPDATE post SET  WHERE post.id = %(id_1)s]
[parameters: {'id_1': '15'}]
(Background on this error at: http://sqlalche.me/e/13/f405)
 

[2021-03-18 11:17:23] [ERROR] Traceback (most recent call last):
  File "/mnt/data/projects/python/webapp/flask/engilogic/v3/venv/lib/python3.8/site-packages/mysql/connector/connection_cext.py", line 507, in cmd_query
    self._cmysql.query(query,
_mysql_connector.MySQLInterfaceError: You have an error in your SQL syntax; check the manual that corresponds to your MySQL server version for the right syntax to use near 'WHERE post.id = '27'' at line 1

During handling of the above exception, another exception occurred:

Traceback (most recent call last):
  File "/mnt/data/projects/python/webapp/flask/engilogic/v3/venv/lib/python3.8/site-packages/sqlalchemy/engine/base.py", line 1276, in _execute_context
    self.dialect.do_execute(
  File "/mnt/data/projects/python/webapp/flask/engilogic/v3/venv/lib/python3.8/site-packages/sqlalchemy/engine/default.py", line 608, in do_execute
    cursor.execute(statement, parameters)
  File "/mnt/data/projects/python/webapp/flask/engilogic/v3/venv/lib/python3.8/site-packages/mysql/connector/cursor_cext.py", line 274, in execute
    result = self._cnx.cmd_query(stmt, raw=self._raw,
  File "/mnt/data/projects/python/webapp/flask/engilogic/v3/venv/lib/python3.8/site-packages/mysql/connector/connection_cext.py", line 511, in cmd_query
    raise errors.get_mysql_exception(exc.errno, msg=exc.msg,
mysql.connector.errors.ProgrammingError: 1064 (42000): You have an error in your SQL syntax; check the manual that corresponds to your MySQL server version for the right syntax to use near 'WHERE post.id = '27'' at line 1

The above exception was the direct cause of the following exception:

Traceback (most recent call last):
  File "/mnt/data/projects/python/webapp/flask/engilogic/v3/webapp/app/admin/view_admin.py", line 137, in dyn_edit
    res = Model.query.filter(Model.id == id).update(data)
  File "/mnt/data/projects/python/webapp/flask/engilogic/v3/venv/lib/python3.8/site-packages/sqlalchemy/orm/query.py", line 4063, in update
    update_op.exec_()
  File "/mnt/data/projects/python/webapp/flask/engilogic/v3/venv/lib/python3.8/site-packages/sqlalchemy/orm/persistence.py", line 1697, in exec_
    self._do_exec()
  File "/mnt/data/projects/python/webapp/flask/engilogic/v3/venv/lib/python3.8/site-packages/sqlalchemy/orm/persistence.py", line 1895, in _do_exec
    self._execute_stmt(update_stmt)
  File "/mnt/data/projects/python/webapp/flask/engilogic/v3/venv/lib/python3.8/site-packages/sqlalchemy/orm/persistence.py", line 1702, in _execute_stmt
    self.result = self.query._execute_crud(stmt, self.mapper)
  File "/mnt/data/projects/python/webapp/flask/engilogic/v3/venv/lib/python3.8/site-packages/sqlalchemy/orm/query.py", line 3568, in _execute_crud
    return conn.execute(stmt, self._params)
  File "/mnt/data/projects/python/webapp/flask/engilogic/v3/venv/lib/python3.8/site-packages/sqlalchemy/engine/base.py", line 1011, in execute
    return meth(self, multiparams, params)
  File "/mnt/data/projects/python/webapp/flask/engilogic/v3/venv/lib/python3.8/site-packages/sqlalchemy/sql/elements.py", line 298, in _execute_on_connection
    return connection._execute_clauseelement(self, multiparams, params)
  File "/mnt/data/projects/python/webapp/flask/engilogic/v3/venv/lib/python3.8/site-packages/sqlalchemy/engine/base.py", line 1124, in _execute_clauseelement
    ret = self._execute_context(
  File "/mnt/data/projects/python/webapp/flask/engilogic/v3/venv/lib/python3.8/site-packages/sqlalchemy/engine/base.py", line 1316, in _execute_context
    self._handle_dbapi_exception(
  File "/mnt/data/projects/python/webapp/flask/engilogic/v3/venv/lib/python3.8/site-packages/sqlalchemy/engine/base.py", line 1510, in _handle_dbapi_exception
    util.raise_(
  File "/mnt/data/projects/python/webapp/flask/engilogic/v3/venv/lib/python3.8/site-packages/sqlalchemy/util/compat.py", line 182, in raise_
    raise exception
  File "/mnt/data/projects/python/webapp/flask/engilogic/v3/venv/lib/python3.8/site-packages/sqlalchemy/engine/base.py", line 1276, in _execute_context
    self.dialect.do_execute(
  File "/mnt/data/projects/python/webapp/flask/engilogic/v3/venv/lib/python3.8/site-packages/sqlalchemy/engine/default.py", line 608, in do_execute
    cursor.execute(statement, parameters)
  File "/mnt/data/projects/python/webapp/flask/engilogic/v3/venv/lib/python3.8/site-packages/mysql/connector/cursor_cext.py", line 274, in execute
    result = self._cnx.cmd_query(stmt, raw=self._raw,
  File "/mnt/data/projects/python/webapp/flask/engilogic/v3/venv/lib/python3.8/site-packages/mysql/connector/connection_cext.py", line 511, in cmd_query
    raise errors.get_mysql_exception(exc.errno, msg=exc.msg,
sqlalchemy.exc.ProgrammingError: (mysql.connector.errors.ProgrammingError) 1064 (42000): You have an error in your SQL syntax; check the manual that corresponds to your MySQL server version for the right syntax to use near 'WHERE post.id = '27'' at line 1
[SQL: UPDATE post SET  WHERE post.id = %(id_1)s]
[parameters: {'id_1': '27'}]
(Background on this error at: http://sqlalche.me/e/13/f405)
 

[2021-03-18 11:17:23] [ERROR] Traceback (most recent call last):
  File "/mnt/data/projects/python/webapp/flask/engilogic/v3/venv/lib/python3.8/site-packages/mysql/connector/connection_cext.py", line 507, in cmd_query
    self._cmysql.query(query,
_mysql_connector.MySQLInterfaceError: You have an error in your SQL syntax; check the manual that corresponds to your MySQL server version for the right syntax to use near 'WHERE post.id = '15'' at line 1

During handling of the above exception, another exception occurred:

Traceback (most recent call last):
  File "/mnt/data/projects/python/webapp/flask/engilogic/v3/venv/lib/python3.8/site-packages/sqlalchemy/engine/base.py", line 1276, in _execute_context
    self.dialect.do_execute(
  File "/mnt/data/projects/python/webapp/flask/engilogic/v3/venv/lib/python3.8/site-packages/sqlalchemy/engine/default.py", line 608, in do_execute
    cursor.execute(statement, parameters)
  File "/mnt/data/projects/python/webapp/flask/engilogic/v3/venv/lib/python3.8/site-packages/mysql/connector/cursor_cext.py", line 274, in execute
    result = self._cnx.cmd_query(stmt, raw=self._raw,
  File "/mnt/data/projects/python/webapp/flask/engilogic/v3/venv/lib/python3.8/site-packages/mysql/connector/connection_cext.py", line 511, in cmd_query
    raise errors.get_mysql_exception(exc.errno, msg=exc.msg,
mysql.connector.errors.ProgrammingError: 1064 (42000): You have an error in your SQL syntax; check the manual that corresponds to your MySQL server version for the right syntax to use near 'WHERE post.id = '15'' at line 1

The above exception was the direct cause of the following exception:

Traceback (most recent call last):
  File "/mnt/data/projects/python/webapp/flask/engilogic/v3/webapp/app/admin/view_admin.py", line 137, in dyn_edit
    res = Model.query.filter(Model.id == id).update(data)
  File "/mnt/data/projects/python/webapp/flask/engilogic/v3/venv/lib/python3.8/site-packages/sqlalchemy/orm/query.py", line 4063, in update
    update_op.exec_()
  File "/mnt/data/projects/python/webapp/flask/engilogic/v3/venv/lib/python3.8/site-packages/sqlalchemy/orm/persistence.py", line 1697, in exec_
    self._do_exec()
  File "/mnt/data/projects/python/webapp/flask/engilogic/v3/venv/lib/python3.8/site-packages/sqlalchemy/orm/persistence.py", line 1895, in _do_exec
    self._execute_stmt(update_stmt)
  File "/mnt/data/projects/python/webapp/flask/engilogic/v3/venv/lib/python3.8/site-packages/sqlalchemy/orm/persistence.py", line 1702, in _execute_stmt
    self.result = self.query._execute_crud(stmt, self.mapper)
  File "/mnt/data/projects/python/webapp/flask/engilogic/v3/venv/lib/python3.8/site-packages/sqlalchemy/orm/query.py", line 3568, in _execute_crud
    return conn.execute(stmt, self._params)
  File "/mnt/data/projects/python/webapp/flask/engilogic/v3/venv/lib/python3.8/site-packages/sqlalchemy/engine/base.py", line 1011, in execute
    return meth(self, multiparams, params)
  File "/mnt/data/projects/python/webapp/flask/engilogic/v3/venv/lib/python3.8/site-packages/sqlalchemy/sql/elements.py", line 298, in _execute_on_connection
    return connection._execute_clauseelement(self, multiparams, params)
  File "/mnt/data/projects/python/webapp/flask/engilogic/v3/venv/lib/python3.8/site-packages/sqlalchemy/engine/base.py", line 1124, in _execute_clauseelement
    ret = self._execute_context(
  File "/mnt/data/projects/python/webapp/flask/engilogic/v3/venv/lib/python3.8/site-packages/sqlalchemy/engine/base.py", line 1316, in _execute_context
    self._handle_dbapi_exception(
  File "/mnt/data/projects/python/webapp/flask/engilogic/v3/venv/lib/python3.8/site-packages/sqlalchemy/engine/base.py", line 1510, in _handle_dbapi_exception
    util.raise_(
  File "/mnt/data/projects/python/webapp/flask/engilogic/v3/venv/lib/python3.8/site-packages/sqlalchemy/util/compat.py", line 182, in raise_
    raise exception
  File "/mnt/data/projects/python/webapp/flask/engilogic/v3/venv/lib/python3.8/site-packages/sqlalchemy/engine/base.py", line 1276, in _execute_context
    self.dialect.do_execute(
  File "/mnt/data/projects/python/webapp/flask/engilogic/v3/venv/lib/python3.8/site-packages/sqlalchemy/engine/default.py", line 608, in do_execute
    cursor.execute(statement, parameters)
  File "/mnt/data/projects/python/webapp/flask/engilogic/v3/venv/lib/python3.8/site-packages/mysql/connector/cursor_cext.py", line 274, in execute
    result = self._cnx.cmd_query(stmt, raw=self._raw,
  File "/mnt/data/projects/python/webapp/flask/engilogic/v3/venv/lib/python3.8/site-packages/mysql/connector/connection_cext.py", line 511, in cmd_query
    raise errors.get_mysql_exception(exc.errno, msg=exc.msg,
sqlalchemy.exc.ProgrammingError: (mysql.connector.errors.ProgrammingError) 1064 (42000): You have an error in your SQL syntax; check the manual that corresponds to your MySQL server version for the right syntax to use near 'WHERE post.id = '15'' at line 1
[SQL: UPDATE post SET  WHERE post.id = %(id_1)s]
[parameters: {'id_1': '15'}]
(Background on this error at: http://sqlalche.me/e/13/f405)
 

[2021-03-18 12:32:10] [ERROR] Traceback (most recent call last):
  File "/mnt/data/projects/python/webapp/flask/engilogic/v3/venv/lib/python3.8/site-packages/mysql/connector/connection_cext.py", line 507, in cmd_query
    self._cmysql.query(query,
_mysql_connector.MySQLInterfaceError: You have an error in your SQL syntax; check the manual that corresponds to your MySQL server version for the right syntax to use near 'WHERE post.id = '30'' at line 1

During handling of the above exception, another exception occurred:

Traceback (most recent call last):
  File "/mnt/data/projects/python/webapp/flask/engilogic/v3/venv/lib/python3.8/site-packages/sqlalchemy/engine/base.py", line 1276, in _execute_context
    self.dialect.do_execute(
  File "/mnt/data/projects/python/webapp/flask/engilogic/v3/venv/lib/python3.8/site-packages/sqlalchemy/engine/default.py", line 608, in do_execute
    cursor.execute(statement, parameters)
  File "/mnt/data/projects/python/webapp/flask/engilogic/v3/venv/lib/python3.8/site-packages/mysql/connector/cursor_cext.py", line 274, in execute
    result = self._cnx.cmd_query(stmt, raw=self._raw,
  File "/mnt/data/projects/python/webapp/flask/engilogic/v3/venv/lib/python3.8/site-packages/mysql/connector/connection_cext.py", line 511, in cmd_query
    raise errors.get_mysql_exception(exc.errno, msg=exc.msg,
mysql.connector.errors.ProgrammingError: 1064 (42000): You have an error in your SQL syntax; check the manual that corresponds to your MySQL server version for the right syntax to use near 'WHERE post.id = '30'' at line 1

The above exception was the direct cause of the following exception:

Traceback (most recent call last):
  File "/mnt/data/projects/python/webapp/flask/engilogic/v3/webapp/app/admin/view_admin.py", line 137, in dyn_edit
    res = Model.query.filter(Model.id == id).update(data)
  File "/mnt/data/projects/python/webapp/flask/engilogic/v3/venv/lib/python3.8/site-packages/sqlalchemy/orm/query.py", line 4063, in update
    update_op.exec_()
  File "/mnt/data/projects/python/webapp/flask/engilogic/v3/venv/lib/python3.8/site-packages/sqlalchemy/orm/persistence.py", line 1697, in exec_
    self._do_exec()
  File "/mnt/data/projects/python/webapp/flask/engilogic/v3/venv/lib/python3.8/site-packages/sqlalchemy/orm/persistence.py", line 1895, in _do_exec
    self._execute_stmt(update_stmt)
  File "/mnt/data/projects/python/webapp/flask/engilogic/v3/venv/lib/python3.8/site-packages/sqlalchemy/orm/persistence.py", line 1702, in _execute_stmt
    self.result = self.query._execute_crud(stmt, self.mapper)
  File "/mnt/data/projects/python/webapp/flask/engilogic/v3/venv/lib/python3.8/site-packages/sqlalchemy/orm/query.py", line 3568, in _execute_crud
    return conn.execute(stmt, self._params)
  File "/mnt/data/projects/python/webapp/flask/engilogic/v3/venv/lib/python3.8/site-packages/sqlalchemy/engine/base.py", line 1011, in execute
    return meth(self, multiparams, params)
  File "/mnt/data/projects/python/webapp/flask/engilogic/v3/venv/lib/python3.8/site-packages/sqlalchemy/sql/elements.py", line 298, in _execute_on_connection
    return connection._execute_clauseelement(self, multiparams, params)
  File "/mnt/data/projects/python/webapp/flask/engilogic/v3/venv/lib/python3.8/site-packages/sqlalchemy/engine/base.py", line 1124, in _execute_clauseelement
    ret = self._execute_context(
  File "/mnt/data/projects/python/webapp/flask/engilogic/v3/venv/lib/python3.8/site-packages/sqlalchemy/engine/base.py", line 1316, in _execute_context
    self._handle_dbapi_exception(
  File "/mnt/data/projects/python/webapp/flask/engilogic/v3/venv/lib/python3.8/site-packages/sqlalchemy/engine/base.py", line 1510, in _handle_dbapi_exception
    util.raise_(
  File "/mnt/data/projects/python/webapp/flask/engilogic/v3/venv/lib/python3.8/site-packages/sqlalchemy/util/compat.py", line 182, in raise_
    raise exception
  File "/mnt/data/projects/python/webapp/flask/engilogic/v3/venv/lib/python3.8/site-packages/sqlalchemy/engine/base.py", line 1276, in _execute_context
    self.dialect.do_execute(
  File "/mnt/data/projects/python/webapp/flask/engilogic/v3/venv/lib/python3.8/site-packages/sqlalchemy/engine/default.py", line 608, in do_execute
    cursor.execute(statement, parameters)
  File "/mnt/data/projects/python/webapp/flask/engilogic/v3/venv/lib/python3.8/site-packages/mysql/connector/cursor_cext.py", line 274, in execute
    result = self._cnx.cmd_query(stmt, raw=self._raw,
  File "/mnt/data/projects/python/webapp/flask/engilogic/v3/venv/lib/python3.8/site-packages/mysql/connector/connection_cext.py", line 511, in cmd_query
    raise errors.get_mysql_exception(exc.errno, msg=exc.msg,
sqlalchemy.exc.ProgrammingError: (mysql.connector.errors.ProgrammingError) 1064 (42000): You have an error in your SQL syntax; check the manual that corresponds to your MySQL server version for the right syntax to use near 'WHERE post.id = '30'' at line 1
[SQL: UPDATE post SET  WHERE post.id = %(id_1)s]
[parameters: {'id_1': '30'}]
(Background on this error at: http://sqlalche.me/e/13/f405)
 

[2021-03-18 12:48:33] [ERROR] Traceback (most recent call last):
  File "/mnt/data/projects/python/webapp/flask/engilogic/v3/venv/lib/python3.8/site-packages/mysql/connector/connection_cext.py", line 507, in cmd_query
    self._cmysql.query(query,
_mysql_connector.MySQLInterfaceError: Incorrect datetime value: 'Fri, 12 Mar 2021 19:37:25 GMT' for column 'created' at row 1

During handling of the above exception, another exception occurred:

Traceback (most recent call last):
  File "/mnt/data/projects/python/webapp/flask/engilogic/v3/venv/lib/python3.8/site-packages/sqlalchemy/engine/base.py", line 1276, in _execute_context
    self.dialect.do_execute(
  File "/mnt/data/projects/python/webapp/flask/engilogic/v3/venv/lib/python3.8/site-packages/sqlalchemy/engine/default.py", line 608, in do_execute
    cursor.execute(statement, parameters)
  File "/mnt/data/projects/python/webapp/flask/engilogic/v3/venv/lib/python3.8/site-packages/mysql/connector/cursor_cext.py", line 274, in execute
    result = self._cnx.cmd_query(stmt, raw=self._raw,
  File "/mnt/data/projects/python/webapp/flask/engilogic/v3/venv/lib/python3.8/site-packages/mysql/connector/connection_cext.py", line 511, in cmd_query
    raise errors.get_mysql_exception(exc.errno, msg=exc.msg,
mysql.connector.errors.DataError: 1292 (22007): Incorrect datetime value: 'Fri, 12 Mar 2021 19:37:25 GMT' for column 'created' at row 1

The above exception was the direct cause of the following exception:

Traceback (most recent call last):
  File "/mnt/data/projects/python/webapp/flask/engilogic/v3/webapp/app/admin/view_admin.py", line 140, in dyn_edit
    res = Model.query.filter(Model.id == id).update(data)
  File "/mnt/data/projects/python/webapp/flask/engilogic/v3/venv/lib/python3.8/site-packages/sqlalchemy/orm/query.py", line 4063, in update
    update_op.exec_()
  File "/mnt/data/projects/python/webapp/flask/engilogic/v3/venv/lib/python3.8/site-packages/sqlalchemy/orm/persistence.py", line 1697, in exec_
    self._do_exec()
  File "/mnt/data/projects/python/webapp/flask/engilogic/v3/venv/lib/python3.8/site-packages/sqlalchemy/orm/persistence.py", line 1895, in _do_exec
    self._execute_stmt(update_stmt)
  File "/mnt/data/projects/python/webapp/flask/engilogic/v3/venv/lib/python3.8/site-packages/sqlalchemy/orm/persistence.py", line 1702, in _execute_stmt
    self.result = self.query._execute_crud(stmt, self.mapper)
  File "/mnt/data/projects/python/webapp/flask/engilogic/v3/venv/lib/python3.8/site-packages/sqlalchemy/orm/query.py", line 3568, in _execute_crud
    return conn.execute(stmt, self._params)
  File "/mnt/data/projects/python/webapp/flask/engilogic/v3/venv/lib/python3.8/site-packages/sqlalchemy/engine/base.py", line 1011, in execute
    return meth(self, multiparams, params)
  File "/mnt/data/projects/python/webapp/flask/engilogic/v3/venv/lib/python3.8/site-packages/sqlalchemy/sql/elements.py", line 298, in _execute_on_connection
    return connection._execute_clauseelement(self, multiparams, params)
  File "/mnt/data/projects/python/webapp/flask/engilogic/v3/venv/lib/python3.8/site-packages/sqlalchemy/engine/base.py", line 1124, in _execute_clauseelement
    ret = self._execute_context(
  File "/mnt/data/projects/python/webapp/flask/engilogic/v3/venv/lib/python3.8/site-packages/sqlalchemy/engine/base.py", line 1316, in _execute_context
    self._handle_dbapi_exception(
  File "/mnt/data/projects/python/webapp/flask/engilogic/v3/venv/lib/python3.8/site-packages/sqlalchemy/engine/base.py", line 1510, in _handle_dbapi_exception
    util.raise_(
  File "/mnt/data/projects/python/webapp/flask/engilogic/v3/venv/lib/python3.8/site-packages/sqlalchemy/util/compat.py", line 182, in raise_
    raise exception
  File "/mnt/data/projects/python/webapp/flask/engilogic/v3/venv/lib/python3.8/site-packages/sqlalchemy/engine/base.py", line 1276, in _execute_context
    self.dialect.do_execute(
  File "/mnt/data/projects/python/webapp/flask/engilogic/v3/venv/lib/python3.8/site-packages/sqlalchemy/engine/default.py", line 608, in do_execute
    cursor.execute(statement, parameters)
  File "/mnt/data/projects/python/webapp/flask/engilogic/v3/venv/lib/python3.8/site-packages/mysql/connector/cursor_cext.py", line 274, in execute
    result = self._cnx.cmd_query(stmt, raw=self._raw,
  File "/mnt/data/projects/python/webapp/flask/engilogic/v3/venv/lib/python3.8/site-packages/mysql/connector/connection_cext.py", line 511, in cmd_query
    raise errors.get_mysql_exception(exc.errno, msg=exc.msg,
sqlalchemy.exc.DataError: (mysql.connector.errors.DataError) 1292 (22007): Incorrect datetime value: 'Fri, 12 Mar 2021 19:37:25 GMT' for column 'created' at row 1
[SQL: UPDATE post SET title=%(title)s, slug=%(slug)s, body=%(body)s, created=%(created)s WHERE post.id = %(id_1)s]
[parameters: {'title': 'Version: #0.0.11', 'slug': 'version-0-0-1-1615573751.387908', 'body': '<p>*) добавлена нумерация страниц\r\n</p><p>*) добавлена форма создания поста\r\n</p><p>*) добавлены теги и связь с постами\r\n</p><p>*) добавлен поиск по постам\r\n</p><p>*) изменено представление постов на "гармошку"</p>', 'created': 'Fri, 12 Mar 2021 19:37:25 GMT', 'id_1': '15'}]
(Background on this error at: http://sqlalche.me/e/13/9h9h)
 

[2021-03-18 13:42:40] [ERROR] Traceback (most recent call last):
  File "/mnt/data/projects/python/webapp/flask/engilogic/v3/venv/lib/python3.8/site-packages/mysql/connector/connection_cext.py", line 507, in cmd_query
    self._cmysql.query(query,
_mysql_connector.MySQLInterfaceError: Incorrect datetime value: 'Fri, 12 Mar 2021 19:37:25 GMT' for column 'created' at row 1

During handling of the above exception, another exception occurred:

Traceback (most recent call last):
  File "/mnt/data/projects/python/webapp/flask/engilogic/v3/venv/lib/python3.8/site-packages/sqlalchemy/engine/base.py", line 1276, in _execute_context
    self.dialect.do_execute(
  File "/mnt/data/projects/python/webapp/flask/engilogic/v3/venv/lib/python3.8/site-packages/sqlalchemy/engine/default.py", line 608, in do_execute
    cursor.execute(statement, parameters)
  File "/mnt/data/projects/python/webapp/flask/engilogic/v3/venv/lib/python3.8/site-packages/mysql/connector/cursor_cext.py", line 274, in execute
    result = self._cnx.cmd_query(stmt, raw=self._raw,
  File "/mnt/data/projects/python/webapp/flask/engilogic/v3/venv/lib/python3.8/site-packages/mysql/connector/connection_cext.py", line 511, in cmd_query
    raise errors.get_mysql_exception(exc.errno, msg=exc.msg,
mysql.connector.errors.DataError: 1292 (22007): Incorrect datetime value: 'Fri, 12 Mar 2021 19:37:25 GMT' for column 'created' at row 1

The above exception was the direct cause of the following exception:

Traceback (most recent call last):
  File "/mnt/data/projects/python/webapp/flask/engilogic/v3/webapp/app/admin/view_admin.py", line 142, in dyn_edit
    res = Model.query.filter(Model.id == id).update(data)
  File "/mnt/data/projects/python/webapp/flask/engilogic/v3/venv/lib/python3.8/site-packages/sqlalchemy/orm/query.py", line 4063, in update
    update_op.exec_()
  File "/mnt/data/projects/python/webapp/flask/engilogic/v3/venv/lib/python3.8/site-packages/sqlalchemy/orm/persistence.py", line 1697, in exec_
    self._do_exec()
  File "/mnt/data/projects/python/webapp/flask/engilogic/v3/venv/lib/python3.8/site-packages/sqlalchemy/orm/persistence.py", line 1895, in _do_exec
    self._execute_stmt(update_stmt)
  File "/mnt/data/projects/python/webapp/flask/engilogic/v3/venv/lib/python3.8/site-packages/sqlalchemy/orm/persistence.py", line 1702, in _execute_stmt
    self.result = self.query._execute_crud(stmt, self.mapper)
  File "/mnt/data/projects/python/webapp/flask/engilogic/v3/venv/lib/python3.8/site-packages/sqlalchemy/orm/query.py", line 3568, in _execute_crud
    return conn.execute(stmt, self._params)
  File "/mnt/data/projects/python/webapp/flask/engilogic/v3/venv/lib/python3.8/site-packages/sqlalchemy/engine/base.py", line 1011, in execute
    return meth(self, multiparams, params)
  File "/mnt/data/projects/python/webapp/flask/engilogic/v3/venv/lib/python3.8/site-packages/sqlalchemy/sql/elements.py", line 298, in _execute_on_connection
    return connection._execute_clauseelement(self, multiparams, params)
  File "/mnt/data/projects/python/webapp/flask/engilogic/v3/venv/lib/python3.8/site-packages/sqlalchemy/engine/base.py", line 1124, in _execute_clauseelement
    ret = self._execute_context(
  File "/mnt/data/projects/python/webapp/flask/engilogic/v3/venv/lib/python3.8/site-packages/sqlalchemy/engine/base.py", line 1316, in _execute_context
    self._handle_dbapi_exception(
  File "/mnt/data/projects/python/webapp/flask/engilogic/v3/venv/lib/python3.8/site-packages/sqlalchemy/engine/base.py", line 1510, in _handle_dbapi_exception
    util.raise_(
  File "/mnt/data/projects/python/webapp/flask/engilogic/v3/venv/lib/python3.8/site-packages/sqlalchemy/util/compat.py", line 182, in raise_
    raise exception
  File "/mnt/data/projects/python/webapp/flask/engilogic/v3/venv/lib/python3.8/site-packages/sqlalchemy/engine/base.py", line 1276, in _execute_context
    self.dialect.do_execute(
  File "/mnt/data/projects/python/webapp/flask/engilogic/v3/venv/lib/python3.8/site-packages/sqlalchemy/engine/default.py", line 608, in do_execute
    cursor.execute(statement, parameters)
  File "/mnt/data/projects/python/webapp/flask/engilogic/v3/venv/lib/python3.8/site-packages/mysql/connector/cursor_cext.py", line 274, in execute
    result = self._cnx.cmd_query(stmt, raw=self._raw,
  File "/mnt/data/projects/python/webapp/flask/engilogic/v3/venv/lib/python3.8/site-packages/mysql/connector/connection_cext.py", line 511, in cmd_query
    raise errors.get_mysql_exception(exc.errno, msg=exc.msg,
sqlalchemy.exc.DataError: (mysql.connector.errors.DataError) 1292 (22007): Incorrect datetime value: 'Fri, 12 Mar 2021 19:37:25 GMT' for column 'created' at row 1
[SQL: UPDATE post SET title=%(title)s, slug=%(slug)s, body=%(body)s, created=%(created)s WHERE post.id = %(id_1)s]
[parameters: {'title': 'Version: #0.0.1', 'slug': 'version-0-0-1-1615573751.387908', 'body': '<p>*) добавлена нумерация страниц\r\n</p><p>*) добавлена форма создания поста\r\n</p><p>*) добавлены теги и связь с постами\r\n</p><p>*) добавлен поиск по постам\r\n</p><p>*) изменено представление постов на "гармошку"</p>', 'created': 'Fri, 12 Mar 2021 19:37:25 GMT', 'id_1': '15'}]
(Background on this error at: http://sqlalche.me/e/13/9h9h)
 

[2021-03-18 13:52:26] [ERROR] Traceback (most recent call last):
  File "/mnt/data/projects/python/webapp/flask/engilogic/v3/venv/lib/python3.8/site-packages/mysql/connector/connection_cext.py", line 507, in cmd_query
    self._cmysql.query(query,
_mysql_connector.MySQLInterfaceError: Incorrect datetime value: 'Fri, 12 Mar 2021 19:37:25 GMT' for column 'created' at row 1

During handling of the above exception, another exception occurred:

Traceback (most recent call last):
  File "/mnt/data/projects/python/webapp/flask/engilogic/v3/venv/lib/python3.8/site-packages/sqlalchemy/engine/base.py", line 1276, in _execute_context
    self.dialect.do_execute(
  File "/mnt/data/projects/python/webapp/flask/engilogic/v3/venv/lib/python3.8/site-packages/sqlalchemy/engine/default.py", line 608, in do_execute
    cursor.execute(statement, parameters)
  File "/mnt/data/projects/python/webapp/flask/engilogic/v3/venv/lib/python3.8/site-packages/mysql/connector/cursor_cext.py", line 274, in execute
    result = self._cnx.cmd_query(stmt, raw=self._raw,
  File "/mnt/data/projects/python/webapp/flask/engilogic/v3/venv/lib/python3.8/site-packages/mysql/connector/connection_cext.py", line 511, in cmd_query
    raise errors.get_mysql_exception(exc.errno, msg=exc.msg,
mysql.connector.errors.DataError: 1292 (22007): Incorrect datetime value: 'Fri, 12 Mar 2021 19:37:25 GMT' for column 'created' at row 1

The above exception was the direct cause of the following exception:

Traceback (most recent call last):
  File "/mnt/data/projects/python/webapp/flask/engilogic/v3/webapp/app/admin/view_admin.py", line 145, in dyn_edit
    res = Model.query.filter(Model.id == id).update(data)
  File "/mnt/data/projects/python/webapp/flask/engilogic/v3/venv/lib/python3.8/site-packages/sqlalchemy/orm/query.py", line 4063, in update
    update_op.exec_()
  File "/mnt/data/projects/python/webapp/flask/engilogic/v3/venv/lib/python3.8/site-packages/sqlalchemy/orm/persistence.py", line 1697, in exec_
    self._do_exec()
  File "/mnt/data/projects/python/webapp/flask/engilogic/v3/venv/lib/python3.8/site-packages/sqlalchemy/orm/persistence.py", line 1895, in _do_exec
    self._execute_stmt(update_stmt)
  File "/mnt/data/projects/python/webapp/flask/engilogic/v3/venv/lib/python3.8/site-packages/sqlalchemy/orm/persistence.py", line 1702, in _execute_stmt
    self.result = self.query._execute_crud(stmt, self.mapper)
  File "/mnt/data/projects/python/webapp/flask/engilogic/v3/venv/lib/python3.8/site-packages/sqlalchemy/orm/query.py", line 3568, in _execute_crud
    return conn.execute(stmt, self._params)
  File "/mnt/data/projects/python/webapp/flask/engilogic/v3/venv/lib/python3.8/site-packages/sqlalchemy/engine/base.py", line 1011, in execute
    return meth(self, multiparams, params)
  File "/mnt/data/projects/python/webapp/flask/engilogic/v3/venv/lib/python3.8/site-packages/sqlalchemy/sql/elements.py", line 298, in _execute_on_connection
    return connection._execute_clauseelement(self, multiparams, params)
  File "/mnt/data/projects/python/webapp/flask/engilogic/v3/venv/lib/python3.8/site-packages/sqlalchemy/engine/base.py", line 1124, in _execute_clauseelement
    ret = self._execute_context(
  File "/mnt/data/projects/python/webapp/flask/engilogic/v3/venv/lib/python3.8/site-packages/sqlalchemy/engine/base.py", line 1316, in _execute_context
    self._handle_dbapi_exception(
  File "/mnt/data/projects/python/webapp/flask/engilogic/v3/venv/lib/python3.8/site-packages/sqlalchemy/engine/base.py", line 1510, in _handle_dbapi_exception
    util.raise_(
  File "/mnt/data/projects/python/webapp/flask/engilogic/v3/venv/lib/python3.8/site-packages/sqlalchemy/util/compat.py", line 182, in raise_
    raise exception
  File "/mnt/data/projects/python/webapp/flask/engilogic/v3/venv/lib/python3.8/site-packages/sqlalchemy/engine/base.py", line 1276, in _execute_context
    self.dialect.do_execute(
  File "/mnt/data/projects/python/webapp/flask/engilogic/v3/venv/lib/python3.8/site-packages/sqlalchemy/engine/default.py", line 608, in do_execute
    cursor.execute(statement, parameters)
  File "/mnt/data/projects/python/webapp/flask/engilogic/v3/venv/lib/python3.8/site-packages/mysql/connector/cursor_cext.py", line 274, in execute
    result = self._cnx.cmd_query(stmt, raw=self._raw,
  File "/mnt/data/projects/python/webapp/flask/engilogic/v3/venv/lib/python3.8/site-packages/mysql/connector/connection_cext.py", line 511, in cmd_query
    raise errors.get_mysql_exception(exc.errno, msg=exc.msg,
sqlalchemy.exc.DataError: (mysql.connector.errors.DataError) 1292 (22007): Incorrect datetime value: 'Fri, 12 Mar 2021 19:37:25 GMT' for column 'created' at row 1
[SQL: UPDATE post SET title=%(title)s, slug=%(slug)s, body=%(body)s, created=%(created)s WHERE post.id = %(id_1)s]
[parameters: {'title': 'Version: #0.0.1', 'slug': 'version-0-0-1-1615573751.387908', 'body': '<p>*) добавлена нумерация страниц\r\n</p><p>*) добавлена форма создания поста\r\n</p><p>*) добавлены теги и связь с постами\r\n</p><p>*) добавлен поиск по постам\r\n</p><p>*) изменено представление постов на "гармошку"</p>', 'created': 'Fri, 12 Mar 2021 19:37:25 GMT', 'id_1': '15'}]
(Background on this error at: http://sqlalche.me/e/13/9h9h)
 

[2021-03-18 15:57:52] [ERROR] Traceback (most recent call last):
  File "/mnt/data/projects/python/webapp/flask/engilogic/v3/venv/lib/python3.8/site-packages/mysql/connector/connection_cext.py", line 507, in cmd_query
    self._cmysql.query(query,
_mysql_connector.MySQLInterfaceError: Duplicate entry 'version-0-0-1-1615573751.387908' for key 'post.slug'

During handling of the above exception, another exception occurred:

Traceback (most recent call last):
  File "/mnt/data/projects/python/webapp/flask/engilogic/v3/venv/lib/python3.8/site-packages/sqlalchemy/engine/base.py", line 1276, in _execute_context
    self.dialect.do_execute(
  File "/mnt/data/projects/python/webapp/flask/engilogic/v3/venv/lib/python3.8/site-packages/sqlalchemy/engine/default.py", line 608, in do_execute
    cursor.execute(statement, parameters)
  File "/mnt/data/projects/python/webapp/flask/engilogic/v3/venv/lib/python3.8/site-packages/mysql/connector/cursor_cext.py", line 274, in execute
    result = self._cnx.cmd_query(stmt, raw=self._raw,
  File "/mnt/data/projects/python/webapp/flask/engilogic/v3/venv/lib/python3.8/site-packages/mysql/connector/connection_cext.py", line 511, in cmd_query
    raise errors.get_mysql_exception(exc.errno, msg=exc.msg,
mysql.connector.errors.IntegrityError: 1062 (23000): Duplicate entry 'version-0-0-1-1615573751.387908' for key 'post.slug'

The above exception was the direct cause of the following exception:

Traceback (most recent call last):
  File "/mnt/data/projects/python/webapp/flask/engilogic/v3/webapp/app/admin/view_admin.py", line 145, in dyn_edit
    res = Model.query.filter(Model.id == id).update(data)
  File "/mnt/data/projects/python/webapp/flask/engilogic/v3/venv/lib/python3.8/site-packages/sqlalchemy/orm/query.py", line 4063, in update
    update_op.exec_()
  File "/mnt/data/projects/python/webapp/flask/engilogic/v3/venv/lib/python3.8/site-packages/sqlalchemy/orm/persistence.py", line 1697, in exec_
    self._do_exec()
  File "/mnt/data/projects/python/webapp/flask/engilogic/v3/venv/lib/python3.8/site-packages/sqlalchemy/orm/persistence.py", line 1895, in _do_exec
    self._execute_stmt(update_stmt)
  File "/mnt/data/projects/python/webapp/flask/engilogic/v3/venv/lib/python3.8/site-packages/sqlalchemy/orm/persistence.py", line 1702, in _execute_stmt
    self.result = self.query._execute_crud(stmt, self.mapper)
  File "/mnt/data/projects/python/webapp/flask/engilogic/v3/venv/lib/python3.8/site-packages/sqlalchemy/orm/query.py", line 3568, in _execute_crud
    return conn.execute(stmt, self._params)
  File "/mnt/data/projects/python/webapp/flask/engilogic/v3/venv/lib/python3.8/site-packages/sqlalchemy/engine/base.py", line 1011, in execute
    return meth(self, multiparams, params)
  File "/mnt/data/projects/python/webapp/flask/engilogic/v3/venv/lib/python3.8/site-packages/sqlalchemy/sql/elements.py", line 298, in _execute_on_connection
    return connection._execute_clauseelement(self, multiparams, params)
  File "/mnt/data/projects/python/webapp/flask/engilogic/v3/venv/lib/python3.8/site-packages/sqlalchemy/engine/base.py", line 1124, in _execute_clauseelement
    ret = self._execute_context(
  File "/mnt/data/projects/python/webapp/flask/engilogic/v3/venv/lib/python3.8/site-packages/sqlalchemy/engine/base.py", line 1316, in _execute_context
    self._handle_dbapi_exception(
  File "/mnt/data/projects/python/webapp/flask/engilogic/v3/venv/lib/python3.8/site-packages/sqlalchemy/engine/base.py", line 1510, in _handle_dbapi_exception
    util.raise_(
  File "/mnt/data/projects/python/webapp/flask/engilogic/v3/venv/lib/python3.8/site-packages/sqlalchemy/util/compat.py", line 182, in raise_
    raise exception
  File "/mnt/data/projects/python/webapp/flask/engilogic/v3/venv/lib/python3.8/site-packages/sqlalchemy/engine/base.py", line 1276, in _execute_context
    self.dialect.do_execute(
  File "/mnt/data/projects/python/webapp/flask/engilogic/v3/venv/lib/python3.8/site-packages/sqlalchemy/engine/default.py", line 608, in do_execute
    cursor.execute(statement, parameters)
  File "/mnt/data/projects/python/webapp/flask/engilogic/v3/venv/lib/python3.8/site-packages/mysql/connector/cursor_cext.py", line 274, in execute
    result = self._cnx.cmd_query(stmt, raw=self._raw,
  File "/mnt/data/projects/python/webapp/flask/engilogic/v3/venv/lib/python3.8/site-packages/mysql/connector/connection_cext.py", line 511, in cmd_query
    raise errors.get_mysql_exception(exc.errno, msg=exc.msg,
sqlalchemy.exc.IntegrityError: (mysql.connector.errors.IntegrityError) 1062 (23000): Duplicate entry 'version-0-0-1-1615573751.387908' for key 'post.slug'
[SQL: UPDATE post SET title=%(title)s, slug=%(slug)s, body=%(body)s, created=%(created)s WHERE post.id = %(id_1)s]
[parameters: {'title': 'Version: #0.0.1', 'slug': 'version-0-0-1-1615573751.387908', 'body': '<p>*) добавлена нумерация страниц\r\n</p><p>*) добавлена форма создания поста\r\n</p><p>*) добавлены теги и связь с постами\r\n</p><p>*) добавлен поиск по постам\r\n</p><p>*) изменено представление постов на "гармошку"</p>', 'created': '2021-03-12T19:37:25', 'id_1': '30'}]
(Background on this error at: http://sqlalche.me/e/13/gkpj)
 

[2021-03-19 21:06:45] [ERROR] Traceback (most recent call last):
  File "/mnt/data/projects/python/webapp/flask/engilogic/v3/venv/lib/python3.8/site-packages/mysql/connector/connection_cext.py", line 507, in cmd_query
    self._cmysql.query(query,
_mysql_connector.MySQLInterfaceError: Truncated incorrect DOUBLE value: '1-dyn'

During handling of the above exception, another exception occurred:

Traceback (most recent call last):
  File "/mnt/data/projects/python/webapp/flask/engilogic/v3/venv/lib/python3.8/site-packages/sqlalchemy/engine/base.py", line 1276, in _execute_context
    self.dialect.do_execute(
  File "/mnt/data/projects/python/webapp/flask/engilogic/v3/venv/lib/python3.8/site-packages/sqlalchemy/engine/default.py", line 608, in do_execute
    cursor.execute(statement, parameters)
  File "/mnt/data/projects/python/webapp/flask/engilogic/v3/venv/lib/python3.8/site-packages/mysql/connector/cursor_cext.py", line 274, in execute
    result = self._cnx.cmd_query(stmt, raw=self._raw,
  File "/mnt/data/projects/python/webapp/flask/engilogic/v3/venv/lib/python3.8/site-packages/mysql/connector/connection_cext.py", line 511, in cmd_query
    raise errors.get_mysql_exception(exc.errno, msg=exc.msg,
mysql.connector.errors.DataError: 1292 (22007): Truncated incorrect DOUBLE value: '1-dyn'

The above exception was the direct cause of the following exception:

Traceback (most recent call last):
  File "/mnt/data/projects/python/webapp/flask/engilogic/v3/webapp/app/admin/view_admin.py", line 135, in dyn_edit
    Model.query.filter(Model.id == id).update(data)
  File "/mnt/data/projects/python/webapp/flask/engilogic/v3/venv/lib/python3.8/site-packages/sqlalchemy/orm/query.py", line 4063, in update
    update_op.exec_()
  File "/mnt/data/projects/python/webapp/flask/engilogic/v3/venv/lib/python3.8/site-packages/sqlalchemy/orm/persistence.py", line 1697, in exec_
    self._do_exec()
  File "/mnt/data/projects/python/webapp/flask/engilogic/v3/venv/lib/python3.8/site-packages/sqlalchemy/orm/persistence.py", line 1895, in _do_exec
    self._execute_stmt(update_stmt)
  File "/mnt/data/projects/python/webapp/flask/engilogic/v3/venv/lib/python3.8/site-packages/sqlalchemy/orm/persistence.py", line 1702, in _execute_stmt
    self.result = self.query._execute_crud(stmt, self.mapper)
  File "/mnt/data/projects/python/webapp/flask/engilogic/v3/venv/lib/python3.8/site-packages/sqlalchemy/orm/query.py", line 3568, in _execute_crud
    return conn.execute(stmt, self._params)
  File "/mnt/data/projects/python/webapp/flask/engilogic/v3/venv/lib/python3.8/site-packages/sqlalchemy/engine/base.py", line 1011, in execute
    return meth(self, multiparams, params)
  File "/mnt/data/projects/python/webapp/flask/engilogic/v3/venv/lib/python3.8/site-packages/sqlalchemy/sql/elements.py", line 298, in _execute_on_connection
    return connection._execute_clauseelement(self, multiparams, params)
  File "/mnt/data/projects/python/webapp/flask/engilogic/v3/venv/lib/python3.8/site-packages/sqlalchemy/engine/base.py", line 1124, in _execute_clauseelement
    ret = self._execute_context(
  File "/mnt/data/projects/python/webapp/flask/engilogic/v3/venv/lib/python3.8/site-packages/sqlalchemy/engine/base.py", line 1316, in _execute_context
    self._handle_dbapi_exception(
  File "/mnt/data/projects/python/webapp/flask/engilogic/v3/venv/lib/python3.8/site-packages/sqlalchemy/engine/base.py", line 1510, in _handle_dbapi_exception
    util.raise_(
  File "/mnt/data/projects/python/webapp/flask/engilogic/v3/venv/lib/python3.8/site-packages/sqlalchemy/util/compat.py", line 182, in raise_
    raise exception
  File "/mnt/data/projects/python/webapp/flask/engilogic/v3/venv/lib/python3.8/site-packages/sqlalchemy/engine/base.py", line 1276, in _execute_context
    self.dialect.do_execute(
  File "/mnt/data/projects/python/webapp/flask/engilogic/v3/venv/lib/python3.8/site-packages/sqlalchemy/engine/default.py", line 608, in do_execute
    cursor.execute(statement, parameters)
  File "/mnt/data/projects/python/webapp/flask/engilogic/v3/venv/lib/python3.8/site-packages/mysql/connector/cursor_cext.py", line 274, in execute
    result = self._cnx.cmd_query(stmt, raw=self._raw,
  File "/mnt/data/projects/python/webapp/flask/engilogic/v3/venv/lib/python3.8/site-packages/mysql/connector/connection_cext.py", line 511, in cmd_query
    raise errors.get_mysql_exception(exc.errno, msg=exc.msg,
sqlalchemy.exc.DataError: (mysql.connector.errors.DataError) 1292 (22007): Truncated incorrect DOUBLE value: '1-dyn'
[SQL: UPDATE customer SET lastname=%(lastname)s, name=%(name)s, issuenum=%(issuenum)s, phone=%(phone)s, email=%(email)s, deliverydate=%(deliverydate)s, message=%(message)s, `isEnabled`=%(isEnabled)s, `status`=%(status)s, `lastMessageId`=%(lastMessageId)s, lastsenddate=%(lastsenddate)s WHERE customer.id = %(id_1)s]
[parameters: {'lastname': 'Шибанов', 'name': 'Андрей', 'issuenum': '1', 'phone': '89161245204', 'email': 'greenleprikon@gmail.com', 'deliverydate': '', 'message': 'test', 'isEnabled': 'No', 'status': 'ok', 'lastMessageId': '', 'lastsenddate': '', 'id_1': '1-dyn'}]
(Background on this error at: http://sqlalche.me/e/13/9h9h)
 

[2021-03-19 21:09:57] [ERROR] Traceback (most recent call last):
  File "/mnt/data/projects/python/webapp/flask/engilogic/v3/venv/lib/python3.8/site-packages/mysql/connector/connection_cext.py", line 507, in cmd_query
    self._cmysql.query(query,
_mysql_connector.MySQLInterfaceError: Truncated incorrect DOUBLE value: '1-dyn'

During handling of the above exception, another exception occurred:

Traceback (most recent call last):
  File "/mnt/data/projects/python/webapp/flask/engilogic/v3/venv/lib/python3.8/site-packages/sqlalchemy/engine/base.py", line 1276, in _execute_context
    self.dialect.do_execute(
  File "/mnt/data/projects/python/webapp/flask/engilogic/v3/venv/lib/python3.8/site-packages/sqlalchemy/engine/default.py", line 608, in do_execute
    cursor.execute(statement, parameters)
  File "/mnt/data/projects/python/webapp/flask/engilogic/v3/venv/lib/python3.8/site-packages/mysql/connector/cursor_cext.py", line 274, in execute
    result = self._cnx.cmd_query(stmt, raw=self._raw,
  File "/mnt/data/projects/python/webapp/flask/engilogic/v3/venv/lib/python3.8/site-packages/mysql/connector/connection_cext.py", line 511, in cmd_query
    raise errors.get_mysql_exception(exc.errno, msg=exc.msg,
mysql.connector.errors.DataError: 1292 (22007): Truncated incorrect DOUBLE value: '1-dyn'

The above exception was the direct cause of the following exception:

Traceback (most recent call last):
  File "/mnt/data/projects/python/webapp/flask/engilogic/v3/webapp/app/admin/view_admin.py", line 135, in dyn_edit
    Model.query.filter(Model.id == id).update(data)
  File "/mnt/data/projects/python/webapp/flask/engilogic/v3/venv/lib/python3.8/site-packages/sqlalchemy/orm/query.py", line 4063, in update
    update_op.exec_()
  File "/mnt/data/projects/python/webapp/flask/engilogic/v3/venv/lib/python3.8/site-packages/sqlalchemy/orm/persistence.py", line 1697, in exec_
    self._do_exec()
  File "/mnt/data/projects/python/webapp/flask/engilogic/v3/venv/lib/python3.8/site-packages/sqlalchemy/orm/persistence.py", line 1895, in _do_exec
    self._execute_stmt(update_stmt)
  File "/mnt/data/projects/python/webapp/flask/engilogic/v3/venv/lib/python3.8/site-packages/sqlalchemy/orm/persistence.py", line 1702, in _execute_stmt
    self.result = self.query._execute_crud(stmt, self.mapper)
  File "/mnt/data/projects/python/webapp/flask/engilogic/v3/venv/lib/python3.8/site-packages/sqlalchemy/orm/query.py", line 3568, in _execute_crud
    return conn.execute(stmt, self._params)
  File "/mnt/data/projects/python/webapp/flask/engilogic/v3/venv/lib/python3.8/site-packages/sqlalchemy/engine/base.py", line 1011, in execute
    return meth(self, multiparams, params)
  File "/mnt/data/projects/python/webapp/flask/engilogic/v3/venv/lib/python3.8/site-packages/sqlalchemy/sql/elements.py", line 298, in _execute_on_connection
    return connection._execute_clauseelement(self, multiparams, params)
  File "/mnt/data/projects/python/webapp/flask/engilogic/v3/venv/lib/python3.8/site-packages/sqlalchemy/engine/base.py", line 1124, in _execute_clauseelement
    ret = self._execute_context(
  File "/mnt/data/projects/python/webapp/flask/engilogic/v3/venv/lib/python3.8/site-packages/sqlalchemy/engine/base.py", line 1316, in _execute_context
    self._handle_dbapi_exception(
  File "/mnt/data/projects/python/webapp/flask/engilogic/v3/venv/lib/python3.8/site-packages/sqlalchemy/engine/base.py", line 1510, in _handle_dbapi_exception
    util.raise_(
  File "/mnt/data/projects/python/webapp/flask/engilogic/v3/venv/lib/python3.8/site-packages/sqlalchemy/util/compat.py", line 182, in raise_
    raise exception
  File "/mnt/data/projects/python/webapp/flask/engilogic/v3/venv/lib/python3.8/site-packages/sqlalchemy/engine/base.py", line 1276, in _execute_context
    self.dialect.do_execute(
  File "/mnt/data/projects/python/webapp/flask/engilogic/v3/venv/lib/python3.8/site-packages/sqlalchemy/engine/default.py", line 608, in do_execute
    cursor.execute(statement, parameters)
  File "/mnt/data/projects/python/webapp/flask/engilogic/v3/venv/lib/python3.8/site-packages/mysql/connector/cursor_cext.py", line 274, in execute
    result = self._cnx.cmd_query(stmt, raw=self._raw,
  File "/mnt/data/projects/python/webapp/flask/engilogic/v3/venv/lib/python3.8/site-packages/mysql/connector/connection_cext.py", line 511, in cmd_query
    raise errors.get_mysql_exception(exc.errno, msg=exc.msg,
sqlalchemy.exc.DataError: (mysql.connector.errors.DataError) 1292 (22007): Truncated incorrect DOUBLE value: '1-dyn'
[SQL: UPDATE customer SET lastname=%(lastname)s, name=%(name)s, issuenum=%(issuenum)s, phone=%(phone)s, email=%(email)s, deliverydate=%(deliverydate)s, message=%(message)s, `isEnabled`=%(isEnabled)s, `status`=%(status)s, `lastMessageId`=%(lastMessageId)s, lastsenddate=%(lastsenddate)s WHERE customer.id = %(id_1)s]
[parameters: {'lastname': 'Шибанов1', 'name': 'Андрей Шибанов', 'issuenum': '1', 'phone': '89161245204', 'email': 'greenleprikon@gmail.com', 'deliverydate': '', 'message': 'test', 'isEnabled': 'No', 'status': 'ok', 'lastMessageId': '', 'lastsenddate': '', 'id_1': '1-dyn'}]
(Background on this error at: http://sqlalche.me/e/13/9h9h)
 

[2021-03-19 21:13:35] [ERROR] Traceback (most recent call last):
  File "/mnt/data/projects/python/webapp/flask/engilogic/v3/venv/lib/python3.8/site-packages/mysql/connector/connection_cext.py", line 507, in cmd_query
    self._cmysql.query(query,
_mysql_connector.MySQLInterfaceError: Truncated incorrect DOUBLE value: '1-dyn'

During handling of the above exception, another exception occurred:

Traceback (most recent call last):
  File "/mnt/data/projects/python/webapp/flask/engilogic/v3/venv/lib/python3.8/site-packages/sqlalchemy/engine/base.py", line 1276, in _execute_context
    self.dialect.do_execute(
  File "/mnt/data/projects/python/webapp/flask/engilogic/v3/venv/lib/python3.8/site-packages/sqlalchemy/engine/default.py", line 608, in do_execute
    cursor.execute(statement, parameters)
  File "/mnt/data/projects/python/webapp/flask/engilogic/v3/venv/lib/python3.8/site-packages/mysql/connector/cursor_cext.py", line 274, in execute
    result = self._cnx.cmd_query(stmt, raw=self._raw,
  File "/mnt/data/projects/python/webapp/flask/engilogic/v3/venv/lib/python3.8/site-packages/mysql/connector/connection_cext.py", line 511, in cmd_query
    raise errors.get_mysql_exception(exc.errno, msg=exc.msg,
mysql.connector.errors.DataError: 1292 (22007): Truncated incorrect DOUBLE value: '1-dyn'

The above exception was the direct cause of the following exception:

Traceback (most recent call last):
  File "/mnt/data/projects/python/webapp/flask/engilogic/v3/webapp/app/admin/view_admin.py", line 135, in dyn_edit
    Model.query.filter(Model.id == id).update(data)
  File "/mnt/data/projects/python/webapp/flask/engilogic/v3/venv/lib/python3.8/site-packages/sqlalchemy/orm/query.py", line 4063, in update
    update_op.exec_()
  File "/mnt/data/projects/python/webapp/flask/engilogic/v3/venv/lib/python3.8/site-packages/sqlalchemy/orm/persistence.py", line 1697, in exec_
    self._do_exec()
  File "/mnt/data/projects/python/webapp/flask/engilogic/v3/venv/lib/python3.8/site-packages/sqlalchemy/orm/persistence.py", line 1895, in _do_exec
    self._execute_stmt(update_stmt)
  File "/mnt/data/projects/python/webapp/flask/engilogic/v3/venv/lib/python3.8/site-packages/sqlalchemy/orm/persistence.py", line 1702, in _execute_stmt
    self.result = self.query._execute_crud(stmt, self.mapper)
  File "/mnt/data/projects/python/webapp/flask/engilogic/v3/venv/lib/python3.8/site-packages/sqlalchemy/orm/query.py", line 3568, in _execute_crud
    return conn.execute(stmt, self._params)
  File "/mnt/data/projects/python/webapp/flask/engilogic/v3/venv/lib/python3.8/site-packages/sqlalchemy/engine/base.py", line 1011, in execute
    return meth(self, multiparams, params)
  File "/mnt/data/projects/python/webapp/flask/engilogic/v3/venv/lib/python3.8/site-packages/sqlalchemy/sql/elements.py", line 298, in _execute_on_connection
    return connection._execute_clauseelement(self, multiparams, params)
  File "/mnt/data/projects/python/webapp/flask/engilogic/v3/venv/lib/python3.8/site-packages/sqlalchemy/engine/base.py", line 1124, in _execute_clauseelement
    ret = self._execute_context(
  File "/mnt/data/projects/python/webapp/flask/engilogic/v3/venv/lib/python3.8/site-packages/sqlalchemy/engine/base.py", line 1316, in _execute_context
    self._handle_dbapi_exception(
  File "/mnt/data/projects/python/webapp/flask/engilogic/v3/venv/lib/python3.8/site-packages/sqlalchemy/engine/base.py", line 1510, in _handle_dbapi_exception
    util.raise_(
  File "/mnt/data/projects/python/webapp/flask/engilogic/v3/venv/lib/python3.8/site-packages/sqlalchemy/util/compat.py", line 182, in raise_
    raise exception
  File "/mnt/data/projects/python/webapp/flask/engilogic/v3/venv/lib/python3.8/site-packages/sqlalchemy/engine/base.py", line 1276, in _execute_context
    self.dialect.do_execute(
  File "/mnt/data/projects/python/webapp/flask/engilogic/v3/venv/lib/python3.8/site-packages/sqlalchemy/engine/default.py", line 608, in do_execute
    cursor.execute(statement, parameters)
  File "/mnt/data/projects/python/webapp/flask/engilogic/v3/venv/lib/python3.8/site-packages/mysql/connector/cursor_cext.py", line 274, in execute
    result = self._cnx.cmd_query(stmt, raw=self._raw,
  File "/mnt/data/projects/python/webapp/flask/engilogic/v3/venv/lib/python3.8/site-packages/mysql/connector/connection_cext.py", line 511, in cmd_query
    raise errors.get_mysql_exception(exc.errno, msg=exc.msg,
sqlalchemy.exc.DataError: (mysql.connector.errors.DataError) 1292 (22007): Truncated incorrect DOUBLE value: '1-dyn'
[SQL: UPDATE customer SET lastname=%(lastname)s, name=%(name)s, issuenum=%(issuenum)s, phone=%(phone)s, email=%(email)s, deliverydate=%(deliverydate)s, message=%(message)s, `isEnabled`=%(isEnabled)s, `status`=%(status)s, `lastMessageId`=%(lastMessageId)s, lastsenddate=%(lastsenddate)s WHERE customer.id = %(id_1)s]
[parameters: {'lastname': 'Шибанов', 'name': 'Андрей Шибанов1', 'issuenum': '1', 'phone': '89161245204', 'email': 'greenleprikon@gmail.com', 'deliverydate': '', 'message': 'test', 'isEnabled': 'No', 'status': 'ok', 'lastMessageId': '', 'lastsenddate': '', 'id_1': '1-dyn'}]
(Background on this error at: http://sqlalche.me/e/13/9h9h)
 

[2021-03-19 21:14:13] [ERROR] Traceback (most recent call last):
  File "/mnt/data/projects/python/webapp/flask/engilogic/v3/venv/lib/python3.8/site-packages/mysql/connector/connection_cext.py", line 507, in cmd_query
    self._cmysql.query(query,
_mysql_connector.MySQLInterfaceError: Truncated incorrect DOUBLE value: '39-dyn'

During handling of the above exception, another exception occurred:

Traceback (most recent call last):
  File "/mnt/data/projects/python/webapp/flask/engilogic/v3/venv/lib/python3.8/site-packages/sqlalchemy/engine/base.py", line 1276, in _execute_context
    self.dialect.do_execute(
  File "/mnt/data/projects/python/webapp/flask/engilogic/v3/venv/lib/python3.8/site-packages/sqlalchemy/engine/default.py", line 608, in do_execute
    cursor.execute(statement, parameters)
  File "/mnt/data/projects/python/webapp/flask/engilogic/v3/venv/lib/python3.8/site-packages/mysql/connector/cursor_cext.py", line 274, in execute
    result = self._cnx.cmd_query(stmt, raw=self._raw,
  File "/mnt/data/projects/python/webapp/flask/engilogic/v3/venv/lib/python3.8/site-packages/mysql/connector/connection_cext.py", line 511, in cmd_query
    raise errors.get_mysql_exception(exc.errno, msg=exc.msg,
mysql.connector.errors.DataError: 1292 (22007): Truncated incorrect DOUBLE value: '39-dyn'

The above exception was the direct cause of the following exception:

Traceback (most recent call last):
  File "/mnt/data/projects/python/webapp/flask/engilogic/v3/webapp/app/admin/view_admin.py", line 135, in dyn_edit
    Model.query.filter(Model.id == id).update(data)
  File "/mnt/data/projects/python/webapp/flask/engilogic/v3/venv/lib/python3.8/site-packages/sqlalchemy/orm/query.py", line 4063, in update
    update_op.exec_()
  File "/mnt/data/projects/python/webapp/flask/engilogic/v3/venv/lib/python3.8/site-packages/sqlalchemy/orm/persistence.py", line 1697, in exec_
    self._do_exec()
  File "/mnt/data/projects/python/webapp/flask/engilogic/v3/venv/lib/python3.8/site-packages/sqlalchemy/orm/persistence.py", line 1895, in _do_exec
    self._execute_stmt(update_stmt)
  File "/mnt/data/projects/python/webapp/flask/engilogic/v3/venv/lib/python3.8/site-packages/sqlalchemy/orm/persistence.py", line 1702, in _execute_stmt
    self.result = self.query._execute_crud(stmt, self.mapper)
  File "/mnt/data/projects/python/webapp/flask/engilogic/v3/venv/lib/python3.8/site-packages/sqlalchemy/orm/query.py", line 3568, in _execute_crud
    return conn.execute(stmt, self._params)
  File "/mnt/data/projects/python/webapp/flask/engilogic/v3/venv/lib/python3.8/site-packages/sqlalchemy/engine/base.py", line 1011, in execute
    return meth(self, multiparams, params)
  File "/mnt/data/projects/python/webapp/flask/engilogic/v3/venv/lib/python3.8/site-packages/sqlalchemy/sql/elements.py", line 298, in _execute_on_connection
    return connection._execute_clauseelement(self, multiparams, params)
  File "/mnt/data/projects/python/webapp/flask/engilogic/v3/venv/lib/python3.8/site-packages/sqlalchemy/engine/base.py", line 1124, in _execute_clauseelement
    ret = self._execute_context(
  File "/mnt/data/projects/python/webapp/flask/engilogic/v3/venv/lib/python3.8/site-packages/sqlalchemy/engine/base.py", line 1316, in _execute_context
    self._handle_dbapi_exception(
  File "/mnt/data/projects/python/webapp/flask/engilogic/v3/venv/lib/python3.8/site-packages/sqlalchemy/engine/base.py", line 1510, in _handle_dbapi_exception
    util.raise_(
  File "/mnt/data/projects/python/webapp/flask/engilogic/v3/venv/lib/python3.8/site-packages/sqlalchemy/util/compat.py", line 182, in raise_
    raise exception
  File "/mnt/data/projects/python/webapp/flask/engilogic/v3/venv/lib/python3.8/site-packages/sqlalchemy/engine/base.py", line 1276, in _execute_context
    self.dialect.do_execute(
  File "/mnt/data/projects/python/webapp/flask/engilogic/v3/venv/lib/python3.8/site-packages/sqlalchemy/engine/default.py", line 608, in do_execute
    cursor.execute(statement, parameters)
  File "/mnt/data/projects/python/webapp/flask/engilogic/v3/venv/lib/python3.8/site-packages/mysql/connector/cursor_cext.py", line 274, in execute
    result = self._cnx.cmd_query(stmt, raw=self._raw,
  File "/mnt/data/projects/python/webapp/flask/engilogic/v3/venv/lib/python3.8/site-packages/mysql/connector/connection_cext.py", line 511, in cmd_query
    raise errors.get_mysql_exception(exc.errno, msg=exc.msg,
sqlalchemy.exc.DataError: (mysql.connector.errors.DataError) 1292 (22007): Truncated incorrect DOUBLE value: '39-dyn'
[SQL: UPDATE post SET title=%(title)s, slug=%(slug)s, body=%(body)s, created=%(created)s WHERE post.id = %(id_1)s]
[parameters: {'title': 'Version: #0.0.11', 'slug': 'version-0-0-1-1616172187.052439', 'body': '<p>*) добавлена нумерация страниц</p><p>*) добавлена форма создания поста\r\n</p><p>*) добавлены теги и связь с постами\r\n</p><p>*) добавлен поиск по постам\r\n</p><p>*) изменено представление постов на "гармошку"</p>', 'created': '2021-03-12 19:37:25', 'id_1': '39-dyn'}]
(Background on this error at: http://sqlalche.me/e/13/9h9h)
 

[2021-03-19 21:24:23] [ERROR] Traceback (most recent call last):
  File "/mnt/data/projects/python/webapp/flask/engilogic/v3/venv/lib/python3.8/site-packages/mysql/connector/connection_cext.py", line 507, in cmd_query
    self._cmysql.query(query,
_mysql_connector.MySQLInterfaceError: Incorrect datetime value: '' for column 'deliverydate' at row 1

During handling of the above exception, another exception occurred:

Traceback (most recent call last):
  File "/mnt/data/projects/python/webapp/flask/engilogic/v3/venv/lib/python3.8/site-packages/sqlalchemy/engine/base.py", line 1276, in _execute_context
    self.dialect.do_execute(
  File "/mnt/data/projects/python/webapp/flask/engilogic/v3/venv/lib/python3.8/site-packages/sqlalchemy/engine/default.py", line 608, in do_execute
    cursor.execute(statement, parameters)
  File "/mnt/data/projects/python/webapp/flask/engilogic/v3/venv/lib/python3.8/site-packages/mysql/connector/cursor_cext.py", line 274, in execute
    result = self._cnx.cmd_query(stmt, raw=self._raw,
  File "/mnt/data/projects/python/webapp/flask/engilogic/v3/venv/lib/python3.8/site-packages/mysql/connector/connection_cext.py", line 511, in cmd_query
    raise errors.get_mysql_exception(exc.errno, msg=exc.msg,
mysql.connector.errors.DataError: 1292 (22007): Incorrect datetime value: '' for column 'deliverydate' at row 1

The above exception was the direct cause of the following exception:

Traceback (most recent call last):
  File "/mnt/data/projects/python/webapp/flask/engilogic/v3/webapp/app/admin/view_admin.py", line 135, in dyn_edit
    Model.query.filter(Model.id == id).update(data)
  File "/mnt/data/projects/python/webapp/flask/engilogic/v3/venv/lib/python3.8/site-packages/sqlalchemy/orm/query.py", line 4063, in update
    update_op.exec_()
  File "/mnt/data/projects/python/webapp/flask/engilogic/v3/venv/lib/python3.8/site-packages/sqlalchemy/orm/persistence.py", line 1697, in exec_
    self._do_exec()
  File "/mnt/data/projects/python/webapp/flask/engilogic/v3/venv/lib/python3.8/site-packages/sqlalchemy/orm/persistence.py", line 1895, in _do_exec
    self._execute_stmt(update_stmt)
  File "/mnt/data/projects/python/webapp/flask/engilogic/v3/venv/lib/python3.8/site-packages/sqlalchemy/orm/persistence.py", line 1702, in _execute_stmt
    self.result = self.query._execute_crud(stmt, self.mapper)
  File "/mnt/data/projects/python/webapp/flask/engilogic/v3/venv/lib/python3.8/site-packages/sqlalchemy/orm/query.py", line 3568, in _execute_crud
    return conn.execute(stmt, self._params)
  File "/mnt/data/projects/python/webapp/flask/engilogic/v3/venv/lib/python3.8/site-packages/sqlalchemy/engine/base.py", line 1011, in execute
    return meth(self, multiparams, params)
  File "/mnt/data/projects/python/webapp/flask/engilogic/v3/venv/lib/python3.8/site-packages/sqlalchemy/sql/elements.py", line 298, in _execute_on_connection
    return connection._execute_clauseelement(self, multiparams, params)
  File "/mnt/data/projects/python/webapp/flask/engilogic/v3/venv/lib/python3.8/site-packages/sqlalchemy/engine/base.py", line 1124, in _execute_clauseelement
    ret = self._execute_context(
  File "/mnt/data/projects/python/webapp/flask/engilogic/v3/venv/lib/python3.8/site-packages/sqlalchemy/engine/base.py", line 1316, in _execute_context
    self._handle_dbapi_exception(
  File "/mnt/data/projects/python/webapp/flask/engilogic/v3/venv/lib/python3.8/site-packages/sqlalchemy/engine/base.py", line 1510, in _handle_dbapi_exception
    util.raise_(
  File "/mnt/data/projects/python/webapp/flask/engilogic/v3/venv/lib/python3.8/site-packages/sqlalchemy/util/compat.py", line 182, in raise_
    raise exception
  File "/mnt/data/projects/python/webapp/flask/engilogic/v3/venv/lib/python3.8/site-packages/sqlalchemy/engine/base.py", line 1276, in _execute_context
    self.dialect.do_execute(
  File "/mnt/data/projects/python/webapp/flask/engilogic/v3/venv/lib/python3.8/site-packages/sqlalchemy/engine/default.py", line 608, in do_execute
    cursor.execute(statement, parameters)
  File "/mnt/data/projects/python/webapp/flask/engilogic/v3/venv/lib/python3.8/site-packages/mysql/connector/cursor_cext.py", line 274, in execute
    result = self._cnx.cmd_query(stmt, raw=self._raw,
  File "/mnt/data/projects/python/webapp/flask/engilogic/v3/venv/lib/python3.8/site-packages/mysql/connector/connection_cext.py", line 511, in cmd_query
    raise errors.get_mysql_exception(exc.errno, msg=exc.msg,
sqlalchemy.exc.DataError: (mysql.connector.errors.DataError) 1292 (22007): Incorrect datetime value: '' for column 'deliverydate' at row 1
[SQL: UPDATE customer SET lastname=%(lastname)s, name=%(name)s, issuenum=%(issuenum)s, phone=%(phone)s, email=%(email)s, deliverydate=%(deliverydate)s, message=%(message)s, `isEnabled`=%(isEnabled)s, `status`=%(status)s, `lastMessageId`=%(lastMessageId)s, lastsenddate=%(lastsenddate)s WHERE customer.id = %(id_1)s]
[parameters: {'lastname': 'Шибанов', 'name': 'Андрей', 'issuenum': '1', 'phone': '89161245204', 'email': 'greenleprikon@gmail.com', 'deliverydate': '', 'message': 'test', 'isEnabled': 'No', 'status': 'ok', 'lastMessageId': '', 'lastsenddate': '', 'id_1': '1'}]
(Background on this error at: http://sqlalche.me/e/13/9h9h)
 

[2021-03-19 21:26:41] [ERROR] Traceback (most recent call last):
  File "/mnt/data/projects/python/webapp/flask/engilogic/v3/venv/lib/python3.8/site-packages/mysql/connector/connection_cext.py", line 507, in cmd_query
    self._cmysql.query(query,
_mysql_connector.MySQLInterfaceError: Incorrect datetime value: 'none' for column 'deliverydate' at row 1

During handling of the above exception, another exception occurred:

Traceback (most recent call last):
  File "/mnt/data/projects/python/webapp/flask/engilogic/v3/venv/lib/python3.8/site-packages/sqlalchemy/engine/base.py", line 1276, in _execute_context
    self.dialect.do_execute(
  File "/mnt/data/projects/python/webapp/flask/engilogic/v3/venv/lib/python3.8/site-packages/sqlalchemy/engine/default.py", line 608, in do_execute
    cursor.execute(statement, parameters)
  File "/mnt/data/projects/python/webapp/flask/engilogic/v3/venv/lib/python3.8/site-packages/mysql/connector/cursor_cext.py", line 274, in execute
    result = self._cnx.cmd_query(stmt, raw=self._raw,
  File "/mnt/data/projects/python/webapp/flask/engilogic/v3/venv/lib/python3.8/site-packages/mysql/connector/connection_cext.py", line 511, in cmd_query
    raise errors.get_mysql_exception(exc.errno, msg=exc.msg,
mysql.connector.errors.DataError: 1292 (22007): Incorrect datetime value: 'none' for column 'deliverydate' at row 1

The above exception was the direct cause of the following exception:

Traceback (most recent call last):
  File "/mnt/data/projects/python/webapp/flask/engilogic/v3/webapp/app/admin/view_admin.py", line 135, in dyn_edit
    Model.query.filter(Model.id == id).update(data)
  File "/mnt/data/projects/python/webapp/flask/engilogic/v3/venv/lib/python3.8/site-packages/sqlalchemy/orm/query.py", line 4063, in update
    update_op.exec_()
  File "/mnt/data/projects/python/webapp/flask/engilogic/v3/venv/lib/python3.8/site-packages/sqlalchemy/orm/persistence.py", line 1697, in exec_
    self._do_exec()
  File "/mnt/data/projects/python/webapp/flask/engilogic/v3/venv/lib/python3.8/site-packages/sqlalchemy/orm/persistence.py", line 1895, in _do_exec
    self._execute_stmt(update_stmt)
  File "/mnt/data/projects/python/webapp/flask/engilogic/v3/venv/lib/python3.8/site-packages/sqlalchemy/orm/persistence.py", line 1702, in _execute_stmt
    self.result = self.query._execute_crud(stmt, self.mapper)
  File "/mnt/data/projects/python/webapp/flask/engilogic/v3/venv/lib/python3.8/site-packages/sqlalchemy/orm/query.py", line 3568, in _execute_crud
    return conn.execute(stmt, self._params)
  File "/mnt/data/projects/python/webapp/flask/engilogic/v3/venv/lib/python3.8/site-packages/sqlalchemy/engine/base.py", line 1011, in execute
    return meth(self, multiparams, params)
  File "/mnt/data/projects/python/webapp/flask/engilogic/v3/venv/lib/python3.8/site-packages/sqlalchemy/sql/elements.py", line 298, in _execute_on_connection
    return connection._execute_clauseelement(self, multiparams, params)
  File "/mnt/data/projects/python/webapp/flask/engilogic/v3/venv/lib/python3.8/site-packages/sqlalchemy/engine/base.py", line 1124, in _execute_clauseelement
    ret = self._execute_context(
  File "/mnt/data/projects/python/webapp/flask/engilogic/v3/venv/lib/python3.8/site-packages/sqlalchemy/engine/base.py", line 1316, in _execute_context
    self._handle_dbapi_exception(
  File "/mnt/data/projects/python/webapp/flask/engilogic/v3/venv/lib/python3.8/site-packages/sqlalchemy/engine/base.py", line 1510, in _handle_dbapi_exception
    util.raise_(
  File "/mnt/data/projects/python/webapp/flask/engilogic/v3/venv/lib/python3.8/site-packages/sqlalchemy/util/compat.py", line 182, in raise_
    raise exception
  File "/mnt/data/projects/python/webapp/flask/engilogic/v3/venv/lib/python3.8/site-packages/sqlalchemy/engine/base.py", line 1276, in _execute_context
    self.dialect.do_execute(
  File "/mnt/data/projects/python/webapp/flask/engilogic/v3/venv/lib/python3.8/site-packages/sqlalchemy/engine/default.py", line 608, in do_execute
    cursor.execute(statement, parameters)
  File "/mnt/data/projects/python/webapp/flask/engilogic/v3/venv/lib/python3.8/site-packages/mysql/connector/cursor_cext.py", line 274, in execute
    result = self._cnx.cmd_query(stmt, raw=self._raw,
  File "/mnt/data/projects/python/webapp/flask/engilogic/v3/venv/lib/python3.8/site-packages/mysql/connector/connection_cext.py", line 511, in cmd_query
    raise errors.get_mysql_exception(exc.errno, msg=exc.msg,
sqlalchemy.exc.DataError: (mysql.connector.errors.DataError) 1292 (22007): Incorrect datetime value: 'none' for column 'deliverydate' at row 1
[SQL: UPDATE customer SET lastname=%(lastname)s, name=%(name)s, issuenum=%(issuenum)s, phone=%(phone)s, email=%(email)s, deliverydate=%(deliverydate)s, message=%(message)s, `isEnabled`=%(isEnabled)s, `status`=%(status)s, `lastMessageId`=%(lastMessageId)s, lastsenddate=%(lastsenddate)s WHERE customer.id = %(id_1)s]
[parameters: {'lastname': 'Шибанов', 'name': 'Андрей', 'issuenum': '1', 'phone': '89161245204', 'email': 'greenleprikon@gmail.com', 'deliverydate': 'none', 'message': 'test', 'isEnabled': 'No', 'status': 'ok', 'lastMessageId': '', 'lastsenddate': '', 'id_1': '1'}]
(Background on this error at: http://sqlalche.me/e/13/9h9h)
 

[2021-03-20 11:34:01] [ERROR] Traceback (most recent call last):
  File "/mnt/data/projects/python/webapp/flask/engilogic/v3/venv/lib/python3.8/site-packages/sqlalchemy/orm/base.py", line 406, in _entity_descriptor
    return getattr(entity, key)
AttributeError: type object 'Post' has no attribute 'membership'

The above exception was the direct cause of the following exception:

Traceback (most recent call last):
  File "/mnt/data/projects/python/webapp/flask/engilogic/v3/webapp/app/admin/view_admin.py", line 153, in dyn_edit
    Model.query.filter(Model.id == id).update(data)
  File "/mnt/data/projects/python/webapp/flask/engilogic/v3/venv/lib/python3.8/site-packages/sqlalchemy/orm/query.py", line 4063, in update
    update_op.exec_()
  File "/mnt/data/projects/python/webapp/flask/engilogic/v3/venv/lib/python3.8/site-packages/sqlalchemy/orm/persistence.py", line 1696, in exec_
    self._do_pre_synchronize()
  File "/mnt/data/projects/python/webapp/flask/engilogic/v3/venv/lib/python3.8/site-packages/sqlalchemy/orm/persistence.py", line 1769, in _do_pre_synchronize
    self._additional_evaluators(evaluator_compiler)
  File "/mnt/data/projects/python/webapp/flask/engilogic/v3/venv/lib/python3.8/site-packages/sqlalchemy/orm/persistence.py", line 1943, in _additional_evaluators
    values = self._resolved_values_keys_as_propnames
  File "/mnt/data/projects/python/webapp/flask/engilogic/v3/venv/lib/python3.8/site-packages/sqlalchemy/orm/persistence.py", line 1862, in _resolved_values_keys_as_propnames
    for k, v in self._resolved_values:
  File "/mnt/data/projects/python/webapp/flask/engilogic/v3/venv/lib/python3.8/site-packages/sqlalchemy/orm/persistence.py", line 1849, in _resolved_values
    desc = _entity_descriptor(self.mapper, k)
  File "/mnt/data/projects/python/webapp/flask/engilogic/v3/venv/lib/python3.8/site-packages/sqlalchemy/orm/base.py", line 408, in _entity_descriptor
    util.raise_(
  File "/mnt/data/projects/python/webapp/flask/engilogic/v3/venv/lib/python3.8/site-packages/sqlalchemy/util/compat.py", line 182, in raise_
    raise exception
sqlalchemy.exc.InvalidRequestError: Entity '<class 'app.admin.models.Post'>' has no property 'membership'
 

[2021-03-20 11:34:47] [ERROR] Traceback (most recent call last):
  File "/mnt/data/projects/python/webapp/flask/engilogic/v3/venv/lib/python3.8/site-packages/sqlalchemy/orm/base.py", line 406, in _entity_descriptor
    return getattr(entity, key)
AttributeError: type object 'Tag' has no attribute 'membership'

The above exception was the direct cause of the following exception:

Traceback (most recent call last):
  File "/mnt/data/projects/python/webapp/flask/engilogic/v3/webapp/app/admin/view_admin.py", line 153, in dyn_edit
    Model.query.filter(Model.id == id).update(data)
  File "/mnt/data/projects/python/webapp/flask/engilogic/v3/venv/lib/python3.8/site-packages/sqlalchemy/orm/query.py", line 4063, in update
    update_op.exec_()
  File "/mnt/data/projects/python/webapp/flask/engilogic/v3/venv/lib/python3.8/site-packages/sqlalchemy/orm/persistence.py", line 1696, in exec_
    self._do_pre_synchronize()
  File "/mnt/data/projects/python/webapp/flask/engilogic/v3/venv/lib/python3.8/site-packages/sqlalchemy/orm/persistence.py", line 1769, in _do_pre_synchronize
    self._additional_evaluators(evaluator_compiler)
  File "/mnt/data/projects/python/webapp/flask/engilogic/v3/venv/lib/python3.8/site-packages/sqlalchemy/orm/persistence.py", line 1943, in _additional_evaluators
    values = self._resolved_values_keys_as_propnames
  File "/mnt/data/projects/python/webapp/flask/engilogic/v3/venv/lib/python3.8/site-packages/sqlalchemy/orm/persistence.py", line 1862, in _resolved_values_keys_as_propnames
    for k, v in self._resolved_values:
  File "/mnt/data/projects/python/webapp/flask/engilogic/v3/venv/lib/python3.8/site-packages/sqlalchemy/orm/persistence.py", line 1849, in _resolved_values
    desc = _entity_descriptor(self.mapper, k)
  File "/mnt/data/projects/python/webapp/flask/engilogic/v3/venv/lib/python3.8/site-packages/sqlalchemy/orm/base.py", line 408, in _entity_descriptor
    util.raise_(
  File "/mnt/data/projects/python/webapp/flask/engilogic/v3/venv/lib/python3.8/site-packages/sqlalchemy/util/compat.py", line 182, in raise_
    raise exception
sqlalchemy.exc.InvalidRequestError: Entity '<class 'app.admin.models.Tag'>' has no property 'membership'
 

[2021-03-20 11:38:38] [ERROR] Traceback (most recent call last):
  File "/mnt/data/projects/python/webapp/flask/engilogic/v3/webapp/app/admin/view_admin.py", line 207, in dyn_remove
    cprint("RED", "REQ: {}".format(request.form.getlist()))
TypeError: getlist() missing 1 required positional argument: 'key'
 

[2021-03-21 03:30:24] [ERROR] Traceback (most recent call last):
  File "/mnt/data/projects/python/webapp/flask/engilogic/v3/venv/lib/python3.8/site-packages/mysql/connector/connection_cext.py", line 507, in cmd_query
    self._cmysql.query(query,
_mysql_connector.MySQLInterfaceError: Duplicate entry 'fix-0-0-4-1615755591.05866' for key 'post.slug'

During handling of the above exception, another exception occurred:

Traceback (most recent call last):
  File "/mnt/data/projects/python/webapp/flask/engilogic/v3/venv/lib/python3.8/site-packages/sqlalchemy/engine/base.py", line 1276, in _execute_context
    self.dialect.do_execute(
  File "/mnt/data/projects/python/webapp/flask/engilogic/v3/venv/lib/python3.8/site-packages/sqlalchemy/engine/default.py", line 608, in do_execute
    cursor.execute(statement, parameters)
  File "/mnt/data/projects/python/webapp/flask/engilogic/v3/venv/lib/python3.8/site-packages/mysql/connector/cursor_cext.py", line 274, in execute
    result = self._cnx.cmd_query(stmt, raw=self._raw,
  File "/mnt/data/projects/python/webapp/flask/engilogic/v3/venv/lib/python3.8/site-packages/mysql/connector/connection_cext.py", line 511, in cmd_query
    raise errors.get_mysql_exception(exc.errno, msg=exc.msg,
mysql.connector.errors.IntegrityError: 1062 (23000): Duplicate entry 'fix-0-0-4-1615755591.05866' for key 'post.slug'

The above exception was the direct cause of the following exception:

Traceback (most recent call last):
  File "/mnt/data/projects/python/webapp/flask/engilogic/v3/webapp/app/admin/view_admin.py", line 206, in dyn_edit
    Model.query.filter(Model.id == id).update(data)
  File "/mnt/data/projects/python/webapp/flask/engilogic/v3/venv/lib/python3.8/site-packages/sqlalchemy/orm/query.py", line 4063, in update
    update_op.exec_()
  File "/mnt/data/projects/python/webapp/flask/engilogic/v3/venv/lib/python3.8/site-packages/sqlalchemy/orm/persistence.py", line 1697, in exec_
    self._do_exec()
  File "/mnt/data/projects/python/webapp/flask/engilogic/v3/venv/lib/python3.8/site-packages/sqlalchemy/orm/persistence.py", line 1895, in _do_exec
    self._execute_stmt(update_stmt)
  File "/mnt/data/projects/python/webapp/flask/engilogic/v3/venv/lib/python3.8/site-packages/sqlalchemy/orm/persistence.py", line 1702, in _execute_stmt
    self.result = self.query._execute_crud(stmt, self.mapper)
  File "/mnt/data/projects/python/webapp/flask/engilogic/v3/venv/lib/python3.8/site-packages/sqlalchemy/orm/query.py", line 3568, in _execute_crud
    return conn.execute(stmt, self._params)
  File "/mnt/data/projects/python/webapp/flask/engilogic/v3/venv/lib/python3.8/site-packages/sqlalchemy/engine/base.py", line 1011, in execute
    return meth(self, multiparams, params)
  File "/mnt/data/projects/python/webapp/flask/engilogic/v3/venv/lib/python3.8/site-packages/sqlalchemy/sql/elements.py", line 298, in _execute_on_connection
    return connection._execute_clauseelement(self, multiparams, params)
  File "/mnt/data/projects/python/webapp/flask/engilogic/v3/venv/lib/python3.8/site-packages/sqlalchemy/engine/base.py", line 1124, in _execute_clauseelement
    ret = self._execute_context(
  File "/mnt/data/projects/python/webapp/flask/engilogic/v3/venv/lib/python3.8/site-packages/sqlalchemy/engine/base.py", line 1316, in _execute_context
    self._handle_dbapi_exception(
  File "/mnt/data/projects/python/webapp/flask/engilogic/v3/venv/lib/python3.8/site-packages/sqlalchemy/engine/base.py", line 1510, in _handle_dbapi_exception
    util.raise_(
  File "/mnt/data/projects/python/webapp/flask/engilogic/v3/venv/lib/python3.8/site-packages/sqlalchemy/util/compat.py", line 182, in raise_
    raise exception
  File "/mnt/data/projects/python/webapp/flask/engilogic/v3/venv/lib/python3.8/site-packages/sqlalchemy/engine/base.py", line 1276, in _execute_context
    self.dialect.do_execute(
  File "/mnt/data/projects/python/webapp/flask/engilogic/v3/venv/lib/python3.8/site-packages/sqlalchemy/engine/default.py", line 608, in do_execute
    cursor.execute(statement, parameters)
  File "/mnt/data/projects/python/webapp/flask/engilogic/v3/venv/lib/python3.8/site-packages/mysql/connector/cursor_cext.py", line 274, in execute
    result = self._cnx.cmd_query(stmt, raw=self._raw,
  File "/mnt/data/projects/python/webapp/flask/engilogic/v3/venv/lib/python3.8/site-packages/mysql/connector/connection_cext.py", line 511, in cmd_query
    raise errors.get_mysql_exception(exc.errno, msg=exc.msg,
sqlalchemy.exc.IntegrityError: (mysql.connector.errors.IntegrityError) 1062 (23000): Duplicate entry 'fix-0-0-4-1615755591.05866' for key 'post.slug'
[SQL: UPDATE post SET title=%(title)s, slug=%(slug)s, body=%(body)s, created=%(created)s WHERE post.id = %(id_1)s]
[parameters: {'title': 'Fix: #0.0.4', 'slug': 'fix-0-0-4-1615755591.05866', 'body': '<ul><li>исправлено расположение pagination для мобильного вида</li><li>добавлено ограничение на количество ссылок pages на странице</li></ul>', 'created': '2021-03-14 23:59:51', 'id_1': '26'}]
(Background on this error at: http://sqlalche.me/e/13/gkpj)
 

[2021-03-21 03:32:03] [ERROR] Traceback (most recent call last):
  File "/mnt/data/projects/python/webapp/flask/engilogic/v3/webapp/app/admin/view_admin.py", line 260, in dyn_remove
    db.session.commit()
  File "/mnt/data/projects/python/webapp/flask/engilogic/v3/venv/lib/python3.8/site-packages/sqlalchemy/orm/scoping.py", line 163, in do
    return getattr(self.registry(), name)(*args, **kwargs)
  File "/mnt/data/projects/python/webapp/flask/engilogic/v3/venv/lib/python3.8/site-packages/sqlalchemy/orm/session.py", line 1046, in commit
    self.transaction.commit()
  File "/mnt/data/projects/python/webapp/flask/engilogic/v3/venv/lib/python3.8/site-packages/sqlalchemy/orm/session.py", line 504, in commit
    self._prepare_impl()
  File "/mnt/data/projects/python/webapp/flask/engilogic/v3/venv/lib/python3.8/site-packages/sqlalchemy/orm/session.py", line 483, in _prepare_impl
    self.session.flush()
  File "/mnt/data/projects/python/webapp/flask/engilogic/v3/venv/lib/python3.8/site-packages/sqlalchemy/orm/session.py", line 2540, in flush
    self._flush(objects)
  File "/mnt/data/projects/python/webapp/flask/engilogic/v3/venv/lib/python3.8/site-packages/sqlalchemy/orm/session.py", line 2682, in _flush
    transaction.rollback(_capture_exception=True)
  File "/mnt/data/projects/python/webapp/flask/engilogic/v3/venv/lib/python3.8/site-packages/sqlalchemy/util/langhelpers.py", line 68, in __exit__
    compat.raise_(
  File "/mnt/data/projects/python/webapp/flask/engilogic/v3/venv/lib/python3.8/site-packages/sqlalchemy/util/compat.py", line 182, in raise_
    raise exception
  File "/mnt/data/projects/python/webapp/flask/engilogic/v3/venv/lib/python3.8/site-packages/sqlalchemy/orm/session.py", line 2642, in _flush
    flush_context.execute()
  File "/mnt/data/projects/python/webapp/flask/engilogic/v3/venv/lib/python3.8/site-packages/sqlalchemy/orm/unitofwork.py", line 422, in execute
    rec.execute(self)
  File "/mnt/data/projects/python/webapp/flask/engilogic/v3/venv/lib/python3.8/site-packages/sqlalchemy/orm/unitofwork.py", line 538, in execute
    self.dependency_processor.process_deletes(uow, states)
  File "/mnt/data/projects/python/webapp/flask/engilogic/v3/venv/lib/python3.8/site-packages/sqlalchemy/orm/dependency.py", line 1104, in process_deletes
    self._run_crud(
  File "/mnt/data/projects/python/webapp/flask/engilogic/v3/venv/lib/python3.8/site-packages/sqlalchemy/orm/dependency.py", line 1201, in _run_crud
    raise exc.StaleDataError(
sqlalchemy.orm.exc.StaleDataError: DELETE statement on table 'tag_membership' expected to delete 2 row(s); Only 3 were matched.
 

[2021-03-22 12:39:29] [ERROR] Traceback (most recent call last):
  File "/mnt/data/projects/python/webapp/flask/engilogic/v3/venv/lib/python3.8/site-packages/mysql/connector/connection_cext.py", line 507, in cmd_query
    self._cmysql.query(query,
_mysql_connector.MySQLInterfaceError: Duplicate entry 'asd@test.ru' for key 'user.email'

During handling of the above exception, another exception occurred:

Traceback (most recent call last):
  File "/mnt/data/projects/python/webapp/flask/engilogic/v3/venv/lib/python3.8/site-packages/sqlalchemy/engine/base.py", line 1276, in _execute_context
    self.dialect.do_execute(
  File "/mnt/data/projects/python/webapp/flask/engilogic/v3/venv/lib/python3.8/site-packages/sqlalchemy/engine/default.py", line 608, in do_execute
    cursor.execute(statement, parameters)
  File "/mnt/data/projects/python/webapp/flask/engilogic/v3/venv/lib/python3.8/site-packages/mysql/connector/cursor_cext.py", line 274, in execute
    result = self._cnx.cmd_query(stmt, raw=self._raw,
  File "/mnt/data/projects/python/webapp/flask/engilogic/v3/venv/lib/python3.8/site-packages/mysql/connector/connection_cext.py", line 511, in cmd_query
    raise errors.get_mysql_exception(exc.errno, msg=exc.msg,
mysql.connector.errors.IntegrityError: 1062 (23000): Duplicate entry 'asd@test.ru' for key 'user.email'

The above exception was the direct cause of the following exception:

Traceback (most recent call last):
  File "/mnt/data/projects/python/webapp/flask/engilogic/v3/webapp/app/admin/view_admin.py", line 214, in dyn_edit
    Model.query.filter(Model.id == id).update(data)
  File "/mnt/data/projects/python/webapp/flask/engilogic/v3/venv/lib/python3.8/site-packages/sqlalchemy/orm/query.py", line 4063, in update
    update_op.exec_()
  File "/mnt/data/projects/python/webapp/flask/engilogic/v3/venv/lib/python3.8/site-packages/sqlalchemy/orm/persistence.py", line 1697, in exec_
    self._do_exec()
  File "/mnt/data/projects/python/webapp/flask/engilogic/v3/venv/lib/python3.8/site-packages/sqlalchemy/orm/persistence.py", line 1895, in _do_exec
    self._execute_stmt(update_stmt)
  File "/mnt/data/projects/python/webapp/flask/engilogic/v3/venv/lib/python3.8/site-packages/sqlalchemy/orm/persistence.py", line 1702, in _execute_stmt
    self.result = self.query._execute_crud(stmt, self.mapper)
  File "/mnt/data/projects/python/webapp/flask/engilogic/v3/venv/lib/python3.8/site-packages/sqlalchemy/orm/query.py", line 3568, in _execute_crud
    return conn.execute(stmt, self._params)
  File "/mnt/data/projects/python/webapp/flask/engilogic/v3/venv/lib/python3.8/site-packages/sqlalchemy/engine/base.py", line 1011, in execute
    return meth(self, multiparams, params)
  File "/mnt/data/projects/python/webapp/flask/engilogic/v3/venv/lib/python3.8/site-packages/sqlalchemy/sql/elements.py", line 298, in _execute_on_connection
    return connection._execute_clauseelement(self, multiparams, params)
  File "/mnt/data/projects/python/webapp/flask/engilogic/v3/venv/lib/python3.8/site-packages/sqlalchemy/engine/base.py", line 1124, in _execute_clauseelement
    ret = self._execute_context(
  File "/mnt/data/projects/python/webapp/flask/engilogic/v3/venv/lib/python3.8/site-packages/sqlalchemy/engine/base.py", line 1316, in _execute_context
    self._handle_dbapi_exception(
  File "/mnt/data/projects/python/webapp/flask/engilogic/v3/venv/lib/python3.8/site-packages/sqlalchemy/engine/base.py", line 1510, in _handle_dbapi_exception
    util.raise_(
  File "/mnt/data/projects/python/webapp/flask/engilogic/v3/venv/lib/python3.8/site-packages/sqlalchemy/util/compat.py", line 182, in raise_
    raise exception
  File "/mnt/data/projects/python/webapp/flask/engilogic/v3/venv/lib/python3.8/site-packages/sqlalchemy/engine/base.py", line 1276, in _execute_context
    self.dialect.do_execute(
  File "/mnt/data/projects/python/webapp/flask/engilogic/v3/venv/lib/python3.8/site-packages/sqlalchemy/engine/default.py", line 608, in do_execute
    cursor.execute(statement, parameters)
  File "/mnt/data/projects/python/webapp/flask/engilogic/v3/venv/lib/python3.8/site-packages/mysql/connector/cursor_cext.py", line 274, in execute
    result = self._cnx.cmd_query(stmt, raw=self._raw,
  File "/mnt/data/projects/python/webapp/flask/engilogic/v3/venv/lib/python3.8/site-packages/mysql/connector/connection_cext.py", line 511, in cmd_query
    raise errors.get_mysql_exception(exc.errno, msg=exc.msg,
sqlalchemy.exc.IntegrityError: (mysql.connector.errors.IntegrityError) 1062 (23000): Duplicate entry 'asd@test.ru' for key 'user.email'
[SQL: UPDATE user SET login=%(login)s, email=%(email)s, password=%(password)s, created=%(created)s WHERE user.id = %(id_1)s]
[parameters: {'login': 'asd', 'email': 'asd@test.ru', 'password': 'pbkdf2:sha256:150000$AzEdZHJs$63db997431199164ee02589653222b44d41d0e861777fd7a766c290cde14c1be', 'created': '2021-03-21 18:20:54', 'id_1': '4'}]
(Background on this error at: http://sqlalche.me/e/13/gkpj)
 

[2021-03-22 12:58:09] [ERROR] Traceback (most recent call last):
  File "/mnt/data/projects/python/webapp/flask/engilogic/v3/venv/lib/python3.8/site-packages/sqlalchemy/engine/base.py", line 1204, in _execute_context
    context = constructor(dialect, self, conn, *args)
  File "/mnt/data/projects/python/webapp/flask/engilogic/v3/venv/lib/python3.8/site-packages/sqlalchemy/engine/default.py", line 873, in _init_compiled
    param = dict(
  File "/mnt/data/projects/python/webapp/flask/engilogic/v3/venv/lib/python3.8/site-packages/sqlalchemy/engine/default.py", line 876, in <genexpr>
    processors[key](compiled_params[key])
  File "/mnt/data/projects/python/webapp/flask/engilogic/v3/venv/lib/python3.8/site-packages/sqlalchemy/sql/sqltypes.py", line 1841, in process
    value = _strict_as_bool(value)
  File "/mnt/data/projects/python/webapp/flask/engilogic/v3/venv/lib/python3.8/site-packages/sqlalchemy/sql/sqltypes.py", line 1816, in _strict_as_bool
    raise TypeError("Not a boolean value: %r" % value)
TypeError: Not a boolean value: 'true'

The above exception was the direct cause of the following exception:

Traceback (most recent call last):
  File "/mnt/data/projects/python/webapp/flask/engilogic/v3/webapp/app/admin/view_admin.py", line 214, in dyn_edit
    Model.query.filter(Model.id == id).update(data)
  File "/mnt/data/projects/python/webapp/flask/engilogic/v3/venv/lib/python3.8/site-packages/sqlalchemy/orm/query.py", line 4063, in update
    update_op.exec_()
  File "/mnt/data/projects/python/webapp/flask/engilogic/v3/venv/lib/python3.8/site-packages/sqlalchemy/orm/persistence.py", line 1697, in exec_
    self._do_exec()
  File "/mnt/data/projects/python/webapp/flask/engilogic/v3/venv/lib/python3.8/site-packages/sqlalchemy/orm/persistence.py", line 1895, in _do_exec
    self._execute_stmt(update_stmt)
  File "/mnt/data/projects/python/webapp/flask/engilogic/v3/venv/lib/python3.8/site-packages/sqlalchemy/orm/persistence.py", line 1702, in _execute_stmt
    self.result = self.query._execute_crud(stmt, self.mapper)
  File "/mnt/data/projects/python/webapp/flask/engilogic/v3/venv/lib/python3.8/site-packages/sqlalchemy/orm/query.py", line 3568, in _execute_crud
    return conn.execute(stmt, self._params)
  File "/mnt/data/projects/python/webapp/flask/engilogic/v3/venv/lib/python3.8/site-packages/sqlalchemy/engine/base.py", line 1011, in execute
    return meth(self, multiparams, params)
  File "/mnt/data/projects/python/webapp/flask/engilogic/v3/venv/lib/python3.8/site-packages/sqlalchemy/sql/elements.py", line 298, in _execute_on_connection
    return connection._execute_clauseelement(self, multiparams, params)
  File "/mnt/data/projects/python/webapp/flask/engilogic/v3/venv/lib/python3.8/site-packages/sqlalchemy/engine/base.py", line 1124, in _execute_clauseelement
    ret = self._execute_context(
  File "/mnt/data/projects/python/webapp/flask/engilogic/v3/venv/lib/python3.8/site-packages/sqlalchemy/engine/base.py", line 1206, in _execute_context
    self._handle_dbapi_exception(
  File "/mnt/data/projects/python/webapp/flask/engilogic/v3/venv/lib/python3.8/site-packages/sqlalchemy/engine/base.py", line 1510, in _handle_dbapi_exception
    util.raise_(
  File "/mnt/data/projects/python/webapp/flask/engilogic/v3/venv/lib/python3.8/site-packages/sqlalchemy/util/compat.py", line 182, in raise_
    raise exception
  File "/mnt/data/projects/python/webapp/flask/engilogic/v3/venv/lib/python3.8/site-packages/sqlalchemy/engine/base.py", line 1204, in _execute_context
    context = constructor(dialect, self, conn, *args)
  File "/mnt/data/projects/python/webapp/flask/engilogic/v3/venv/lib/python3.8/site-packages/sqlalchemy/engine/default.py", line 873, in _init_compiled
    param = dict(
  File "/mnt/data/projects/python/webapp/flask/engilogic/v3/venv/lib/python3.8/site-packages/sqlalchemy/engine/default.py", line 876, in <genexpr>
    processors[key](compiled_params[key])
  File "/mnt/data/projects/python/webapp/flask/engilogic/v3/venv/lib/python3.8/site-packages/sqlalchemy/sql/sqltypes.py", line 1841, in process
    value = _strict_as_bool(value)
  File "/mnt/data/projects/python/webapp/flask/engilogic/v3/venv/lib/python3.8/site-packages/sqlalchemy/sql/sqltypes.py", line 1816, in _strict_as_bool
    raise TypeError("Not a boolean value: %r" % value)
sqlalchemy.exc.StatementError: (builtins.TypeError) Not a boolean value: 'true'
[SQL: UPDATE user SET login=%(login)s, email=%(email)s, created=%(created)s, active=%(active)s WHERE user.id = %(id_1)s]
[parameters: [immutabledict({})]]
 

[2021-03-22 12:58:43] [ERROR] Traceback (most recent call last):
  File "/mnt/data/projects/python/webapp/flask/engilogic/v3/venv/lib/python3.8/site-packages/sqlalchemy/engine/base.py", line 1204, in _execute_context
    context = constructor(dialect, self, conn, *args)
  File "/mnt/data/projects/python/webapp/flask/engilogic/v3/venv/lib/python3.8/site-packages/sqlalchemy/engine/default.py", line 873, in _init_compiled
    param = dict(
  File "/mnt/data/projects/python/webapp/flask/engilogic/v3/venv/lib/python3.8/site-packages/sqlalchemy/engine/default.py", line 876, in <genexpr>
    processors[key](compiled_params[key])
  File "/mnt/data/projects/python/webapp/flask/engilogic/v3/venv/lib/python3.8/site-packages/sqlalchemy/sql/sqltypes.py", line 1841, in process
    value = _strict_as_bool(value)
  File "/mnt/data/projects/python/webapp/flask/engilogic/v3/venv/lib/python3.8/site-packages/sqlalchemy/sql/sqltypes.py", line 1816, in _strict_as_bool
    raise TypeError("Not a boolean value: %r" % value)
TypeError: Not a boolean value: 'True'

The above exception was the direct cause of the following exception:

Traceback (most recent call last):
  File "/mnt/data/projects/python/webapp/flask/engilogic/v3/webapp/app/admin/view_admin.py", line 214, in dyn_edit
    Model.query.filter(Model.id == id).update(data)
  File "/mnt/data/projects/python/webapp/flask/engilogic/v3/venv/lib/python3.8/site-packages/sqlalchemy/orm/query.py", line 4063, in update
    update_op.exec_()
  File "/mnt/data/projects/python/webapp/flask/engilogic/v3/venv/lib/python3.8/site-packages/sqlalchemy/orm/persistence.py", line 1697, in exec_
    self._do_exec()
  File "/mnt/data/projects/python/webapp/flask/engilogic/v3/venv/lib/python3.8/site-packages/sqlalchemy/orm/persistence.py", line 1895, in _do_exec
    self._execute_stmt(update_stmt)
  File "/mnt/data/projects/python/webapp/flask/engilogic/v3/venv/lib/python3.8/site-packages/sqlalchemy/orm/persistence.py", line 1702, in _execute_stmt
    self.result = self.query._execute_crud(stmt, self.mapper)
  File "/mnt/data/projects/python/webapp/flask/engilogic/v3/venv/lib/python3.8/site-packages/sqlalchemy/orm/query.py", line 3568, in _execute_crud
    return conn.execute(stmt, self._params)
  File "/mnt/data/projects/python/webapp/flask/engilogic/v3/venv/lib/python3.8/site-packages/sqlalchemy/engine/base.py", line 1011, in execute
    return meth(self, multiparams, params)
  File "/mnt/data/projects/python/webapp/flask/engilogic/v3/venv/lib/python3.8/site-packages/sqlalchemy/sql/elements.py", line 298, in _execute_on_connection
    return connection._execute_clauseelement(self, multiparams, params)
  File "/mnt/data/projects/python/webapp/flask/engilogic/v3/venv/lib/python3.8/site-packages/sqlalchemy/engine/base.py", line 1124, in _execute_clauseelement
    ret = self._execute_context(
  File "/mnt/data/projects/python/webapp/flask/engilogic/v3/venv/lib/python3.8/site-packages/sqlalchemy/engine/base.py", line 1206, in _execute_context
    self._handle_dbapi_exception(
  File "/mnt/data/projects/python/webapp/flask/engilogic/v3/venv/lib/python3.8/site-packages/sqlalchemy/engine/base.py", line 1510, in _handle_dbapi_exception
    util.raise_(
  File "/mnt/data/projects/python/webapp/flask/engilogic/v3/venv/lib/python3.8/site-packages/sqlalchemy/util/compat.py", line 182, in raise_
    raise exception
  File "/mnt/data/projects/python/webapp/flask/engilogic/v3/venv/lib/python3.8/site-packages/sqlalchemy/engine/base.py", line 1204, in _execute_context
    context = constructor(dialect, self, conn, *args)
  File "/mnt/data/projects/python/webapp/flask/engilogic/v3/venv/lib/python3.8/site-packages/sqlalchemy/engine/default.py", line 873, in _init_compiled
    param = dict(
  File "/mnt/data/projects/python/webapp/flask/engilogic/v3/venv/lib/python3.8/site-packages/sqlalchemy/engine/default.py", line 876, in <genexpr>
    processors[key](compiled_params[key])
  File "/mnt/data/projects/python/webapp/flask/engilogic/v3/venv/lib/python3.8/site-packages/sqlalchemy/sql/sqltypes.py", line 1841, in process
    value = _strict_as_bool(value)
  File "/mnt/data/projects/python/webapp/flask/engilogic/v3/venv/lib/python3.8/site-packages/sqlalchemy/sql/sqltypes.py", line 1816, in _strict_as_bool
    raise TypeError("Not a boolean value: %r" % value)
sqlalchemy.exc.StatementError: (builtins.TypeError) Not a boolean value: 'True'
[SQL: UPDATE user SET login=%(login)s, email=%(email)s, created=%(created)s, active=%(active)s WHERE user.id = %(id_1)s]
[parameters: [immutabledict({})]]
 

[2021-03-22 12:58:57] [ERROR] Traceback (most recent call last):
  File "/mnt/data/projects/python/webapp/flask/engilogic/v3/venv/lib/python3.8/site-packages/sqlalchemy/engine/base.py", line 1204, in _execute_context
    context = constructor(dialect, self, conn, *args)
  File "/mnt/data/projects/python/webapp/flask/engilogic/v3/venv/lib/python3.8/site-packages/sqlalchemy/engine/default.py", line 873, in _init_compiled
    param = dict(
  File "/mnt/data/projects/python/webapp/flask/engilogic/v3/venv/lib/python3.8/site-packages/sqlalchemy/engine/default.py", line 876, in <genexpr>
    processors[key](compiled_params[key])
  File "/mnt/data/projects/python/webapp/flask/engilogic/v3/venv/lib/python3.8/site-packages/sqlalchemy/sql/sqltypes.py", line 1841, in process
    value = _strict_as_bool(value)
  File "/mnt/data/projects/python/webapp/flask/engilogic/v3/venv/lib/python3.8/site-packages/sqlalchemy/sql/sqltypes.py", line 1816, in _strict_as_bool
    raise TypeError("Not a boolean value: %r" % value)
TypeError: Not a boolean value: '1'

The above exception was the direct cause of the following exception:

Traceback (most recent call last):
  File "/mnt/data/projects/python/webapp/flask/engilogic/v3/webapp/app/admin/view_admin.py", line 214, in dyn_edit
    Model.query.filter(Model.id == id).update(data)
  File "/mnt/data/projects/python/webapp/flask/engilogic/v3/venv/lib/python3.8/site-packages/sqlalchemy/orm/query.py", line 4063, in update
    update_op.exec_()
  File "/mnt/data/projects/python/webapp/flask/engilogic/v3/venv/lib/python3.8/site-packages/sqlalchemy/orm/persistence.py", line 1697, in exec_
    self._do_exec()
  File "/mnt/data/projects/python/webapp/flask/engilogic/v3/venv/lib/python3.8/site-packages/sqlalchemy/orm/persistence.py", line 1895, in _do_exec
    self._execute_stmt(update_stmt)
  File "/mnt/data/projects/python/webapp/flask/engilogic/v3/venv/lib/python3.8/site-packages/sqlalchemy/orm/persistence.py", line 1702, in _execute_stmt
    self.result = self.query._execute_crud(stmt, self.mapper)
  File "/mnt/data/projects/python/webapp/flask/engilogic/v3/venv/lib/python3.8/site-packages/sqlalchemy/orm/query.py", line 3568, in _execute_crud
    return conn.execute(stmt, self._params)
  File "/mnt/data/projects/python/webapp/flask/engilogic/v3/venv/lib/python3.8/site-packages/sqlalchemy/engine/base.py", line 1011, in execute
    return meth(self, multiparams, params)
  File "/mnt/data/projects/python/webapp/flask/engilogic/v3/venv/lib/python3.8/site-packages/sqlalchemy/sql/elements.py", line 298, in _execute_on_connection
    return connection._execute_clauseelement(self, multiparams, params)
  File "/mnt/data/projects/python/webapp/flask/engilogic/v3/venv/lib/python3.8/site-packages/sqlalchemy/engine/base.py", line 1124, in _execute_clauseelement
    ret = self._execute_context(
  File "/mnt/data/projects/python/webapp/flask/engilogic/v3/venv/lib/python3.8/site-packages/sqlalchemy/engine/base.py", line 1206, in _execute_context
    self._handle_dbapi_exception(
  File "/mnt/data/projects/python/webapp/flask/engilogic/v3/venv/lib/python3.8/site-packages/sqlalchemy/engine/base.py", line 1510, in _handle_dbapi_exception
    util.raise_(
  File "/mnt/data/projects/python/webapp/flask/engilogic/v3/venv/lib/python3.8/site-packages/sqlalchemy/util/compat.py", line 182, in raise_
    raise exception
  File "/mnt/data/projects/python/webapp/flask/engilogic/v3/venv/lib/python3.8/site-packages/sqlalchemy/engine/base.py", line 1204, in _execute_context
    context = constructor(dialect, self, conn, *args)
  File "/mnt/data/projects/python/webapp/flask/engilogic/v3/venv/lib/python3.8/site-packages/sqlalchemy/engine/default.py", line 873, in _init_compiled
    param = dict(
  File "/mnt/data/projects/python/webapp/flask/engilogic/v3/venv/lib/python3.8/site-packages/sqlalchemy/engine/default.py", line 876, in <genexpr>
    processors[key](compiled_params[key])
  File "/mnt/data/projects/python/webapp/flask/engilogic/v3/venv/lib/python3.8/site-packages/sqlalchemy/sql/sqltypes.py", line 1841, in process
    value = _strict_as_bool(value)
  File "/mnt/data/projects/python/webapp/flask/engilogic/v3/venv/lib/python3.8/site-packages/sqlalchemy/sql/sqltypes.py", line 1816, in _strict_as_bool
    raise TypeError("Not a boolean value: %r" % value)
sqlalchemy.exc.StatementError: (builtins.TypeError) Not a boolean value: '1'
[SQL: UPDATE user SET login=%(login)s, email=%(email)s, created=%(created)s, active=%(active)s WHERE user.id = %(id_1)s]
[parameters: [immutabledict({})]]
 

[2021-03-24 15:15:13] [ERROR] Traceback (most recent call last):
  File "/mnt/data/projects/python/webapp/flask/engilogic/v3/webapp/app/get_spreadsheet.py", line 48, in get_spreadheets
    service = build('sheets', 'v4', credentials=self._get_spreadheets())
AttributeError: 'MySpreadSheet' object has no attribute '_get_spreadheets'
 

[2021-03-24 15:16:04] [ERROR] Traceback (most recent call last):
  File "/mnt/data/projects/python/webapp/flask/engilogic/v3/webapp/app/get_spreadsheet.py", line 48, in get_spreadheets
    service = build('sheets', 'v4', credentials=self._get_credentials())
  File "/mnt/data/projects/python/webapp/flask/engilogic/v3/webapp/app/get_spreadsheet.py", line 36, in _get_credentials
    flow = InstalledAppFlow.from_client_secrets_file(self._credentials_file, app.config['SCOPES'])  # here enter the name of your downloaded JSON file
  File "/mnt/data/projects/python/webapp/flask/engilogic/v3/venv/lib/python3.8/site-packages/google_auth_oauthlib/flow.py", line 203, in from_client_secrets_file
    with open(client_secrets_file, "r") as json_file:
FileNotFoundError: [Errno 2] No such file or directory: 'credentials/client_secret.json'
 

[2021-03-24 15:19:15] [ERROR] Traceback (most recent call last):
  File "/mnt/data/projects/python/webapp/flask/engilogic/v3/webapp/app/get_spreadsheet.py", line 48, in get_spreadheets
    service = build('sheets', 'v4', credentials=self._get_credentials())
  File "/mnt/data/projects/python/webapp/flask/engilogic/v3/webapp/app/get_spreadsheet.py", line 29, in _get_credentials
    with open('token.pickle', 'rb') as token:
FileNotFoundError: [Errno 2] No such file or directory: 'token.pickle'
 

[2021-03-24 15:21:36] [ERROR] Traceback (most recent call last):
  File "/mnt/data/projects/python/webapp/flask/engilogic/v3/webapp/app/get_spreadsheet.py", line 50, in get_spreadheets
    service = build('sheets', 'v4', credentials=self._get_credentials())
  File "/mnt/data/projects/python/webapp/flask/engilogic/v3/webapp/app/get_spreadsheet.py", line 31, in _get_credentials
    with open('token.pickle', 'rb') as token:
FileNotFoundError: [Errno 2] No such file or directory: 'token.pickle'
 

[2021-03-24 15:23:15] [ERROR] Traceback (most recent call last):
  File "/mnt/data/projects/python/webapp/flask/engilogic/v3/webapp/app/get_spreadsheet.py", line 57, in get_spreadheets
    service = build('sheets', 'v4', credentials=self._get_credentials())
  File "/mnt/data/projects/python/webapp/flask/engilogic/v3/webapp/app/get_spreadsheet.py", line 32, in _get_credentials
    with open('token.pickle', 'rb') as token:
FileNotFoundError: [Errno 2] No such file or directory: 'token.pickle'
 

[2021-03-25 13:45:58] [ERROR] Traceback (most recent call last):
  File "/mnt/data/projects/python/webapp/flask/engilogic/v3/webapp/app/get_spreadsheet.py", line 137, in get_sheet_values_hard
    for cell in row['values']:
TypeError: string indices must be integers
 

[2021-03-25 14:07:51] [ERROR] Traceback (most recent call last):
  File "/mnt/data/projects/python/webapp/flask/engilogic/v3/webapp/app/get_spreadsheet.py", line 137, in get_sheet_values_hard
    for cell in row[0]['values']:
TypeError: string indices must be integers
 

[2021-03-25 14:20:17] [ERROR] Traceback (most recent call last):
  File "/mnt/data/projects/python/webapp/flask/engilogic/v3/webapp/app/get_spreadsheet.py", line 137, in get_sheet_values_hard
    for cell in row[0]['values']:
KeyError: 0
 

[2021-03-25 14:21:03] [ERROR] Traceback (most recent call last):
  File "/mnt/data/projects/python/webapp/flask/engilogic/v3/webapp/app/get_spreadsheet.py", line 141, in get_sheet_values_hard
    backgroundColor = Color.toHex(cell.get('backgroundColor').get('red'), cell.get('backgroundColor').get('green'), cell.get('backgroundColor').get('blue'))
AttributeError: 'NoneType' object has no attribute 'get'
 

[2021-03-25 14:23:16] [ERROR] Traceback (most recent call last):
  File "/mnt/data/projects/python/webapp/flask/engilogic/v3/webapp/app/get_spreadsheet.py", line 142, in get_sheet_values_hard
    backgroundColor = Color.toHex(cell.get('backgroundColor').get('red'), cell.get('backgroundColor').get('green'), cell.get('backgroundColor').get('blue'))
AttributeError: 'NoneType' object has no attribute 'get'
 

[2021-03-25 14:26:34] [ERROR] Traceback (most recent call last):
  File "/mnt/data/projects/python/webapp/flask/engilogic/v3/webapp/app/get_spreadsheet.py", line 137, in get_sheet_values_hard
    for cell in row['values']:
KeyError: 'values'
 

[2021-03-25 14:41:01] [ERROR] Traceback (most recent call last):
  File "/mnt/data/projects/python/webapp/flask/engilogic/v3/webapp/app/get_spreadsheet.py", line 144, in get_sheet_values_hard
    backgroundColor = Color.toHex(cell.get('userEnteredFormat').get('backgroundColor').get('red'), cell.get('userEnteredFormat').get('backgroundColor').get('green'), cell.get('userEnteredFormat').get('backgroundColor').get('blue'))
TypeError: toHex() takes 1 positional argument but 3 were given
 

[2021-03-25 14:42:18] [ERROR] Traceback (most recent call last):
  File "/mnt/data/projects/python/webapp/flask/engilogic/v3/webapp/app/get_spreadsheet.py", line 144, in get_sheet_values_hard
    backgroundColor = Color(cell.get('userEnteredFormat').get('backgroundColor').get('red'), cell.get('userEnteredFormat').get('backgroundColor').get('green'), cell.get('userEnteredFormat').get('backgroundColor').get('blue')).toHex()
TypeError: toHex() takes 1 positional argument but 3 were given
 

[2021-03-25 14:52:49] [ERROR] Traceback (most recent call last):
  File "/mnt/data/projects/python/webapp/flask/engilogic/v3/webapp/app/get_spreadsheet.py", line 147, in get_sheet_values_hard
    foregroundColor = Color(cell.get('userEnteredFormat').get('textFormat').get('foregroundColor').get('red'), cell.get('userEnteredFormat').get('textFormat').get('foregroundColor').get('green'), cell.get('userEnteredFormat').get('textFormat').get('foregroundColor').get('blue')).toHex()
AttributeError: 'NoneType' object has no attribute 'get'
 

[2021-03-25 15:11:17] [ERROR] Traceback (most recent call last):
  File "/mnt/data/projects/python/webapp/flask/engilogic/v3/webapp/app/get_spreadsheet.py", line 148, in get_sheet_values_hard
    if 'red' in cell.get('userEnteredFormat').get('textFormat').get('foregroundColor'):
AttributeError: 'NoneType' object has no attribute 'get'
 
